Workbook

Sheet Results-VlookUp
A1: Study | B1: box n° | C1: Sample ID number | E1: Type | F1: [IL-33] in pg/mL | G1: IL-33 CV in % | H1: [IL1b] in pg/mL | I1: IL1b CV in % | J1: [IL2] in pg/mL | K1: IL2 CV in % | L1: [IL4] in pg/mL | M1: IL4 CV in % | N1: [IL5] in pg/mL | O1: IL5 CV in % | P1: [IL6] in pg/mL | Q1: IL6 CV in % | R1: [IL8/CXCL8] in pg/mL | S1: IL8/CXCL8 CV in % | T1: [IL10] in pg/mL | U1: IL10 CV in % | V1: [GDF-15] in pg/mL | W1: GDF-15 CV in % | X1: [IL12p70] in pg/mL | Y1: IL12p70 CV in % | Z1: [IL17A/CTLA-8] in pg/mL | AA1: IL17A/CTLA-8 CV in % | AB1: [IFNg] in pg/mL | AC1: IFNg CV in % | AD1: [TNFa] in pg/mL | AE1: TNFa CV in % | AF1: [Granzyme B] in pg/mL | AG1: Granzyme B CV in %
A2: ADRECMO | B2: box 1 | C2: ADRECMO-01_SR_J0 | D2: A001 | E2: serum | F2: =VLOOKUP(D2,'Obs Conc_1'!$C$23:$Q$78,2,FALSE) -> OOR < | G2: =VLOOKUP(D2,'Obs Conc %CV_1'!$C$23:$Q$78,2,FALSE) -> 0 | H2: =VLOOKUP(D2,'Obs Conc_1'!$C$23:$Q$78,3,FALSE) -> OOR < | I2: =VLOOKUP(D2,'Obs Conc %CV_1'!$C$23:$Q$78,3,FALSE) -> 0 | J2: =VLOOKUP(D2,'Obs Conc_1'!$C$23:$Q$78,4,FALSE) -> OOR < | K2: =VLOOKUP(D2,'Obs Conc %CV_1'!$C$23:$Q$78,4,FALSE) -> 0 | L2: =VLOOKUP(D2,'Obs Conc_1'!$C$23:$Q$78,5,FALSE) -> OOR < | M2: =VLOOKUP(D2,'Obs Conc %CV_1'!$C$23:$Q$78,5,FALSE) -> 0 | N2: =VLOOKUP(D2,'Obs Conc_1'!$C$23:$Q$78,6,FALSE) -> OOR < | O2: =VLOOKUP(D2,'Obs Conc %CV_1'!$C$23:$Q$78,6,FALSE) -> 0 | P2: =VLOOKUP(D2,'Obs Conc_1'!$C$23:$Q$78,7,FALSE) -> 25.35 | Q2: =VLOOKUP(D2,'Obs Conc %CV_1'!$C$23:$Q$78,7,FALSE) -> 8.07 | R2: =VLOOKUP(D2,'Obs Conc_1'!$C$23:$Q$78,8,FALSE) -> 9.83 | S2: =VLOOKUP(D2,'Obs Conc %CV_1'!$C$23:$Q$78,8,FALSE) -> 15.32 | T2: =VLOOKUP(D2,'Obs Conc_1'!$C$23:$Q$78,9,FALSE) -> OOR < | U2: =VLOOKUP(D2,'Obs Conc %CV_1'!$C$23:$Q$78,9,FALSE) -> 0 | V2: =VLOOKUP(D2,'Obs Conc_1'!$C$23:$Q$78,10,FALSE) -> 405.42 | W2: =VLOOKUP(D2,'Obs Conc %CV_1'!$C$23:$Q$78,10,FALSE) -> 15.5 | X2: =VLOOKUP(D2,'Obs Conc_1'!$C$23:$Q$78,11,FALSE) -> OOR < | Y2: =VLOOKUP(D2,'Obs Conc %CV_1'!$C$23:$Q$78,11,FALSE) -> 0 | Z2: =VLOOKUP(D2,'Obs Conc_1'!$C$23:$Q$78,12,FALSE) -> OOR < | AA2: =VLOOKUP(D2,'Obs Conc %CV_1'!$C$23:$Q$78,12,FALSE) -> 0 | AB2: =VLOOKUP(D2,'Obs Conc_1'!$C$23:$Q$78,13,FALSE) -> OOR < | AC2: =VLOOKUP(D2,'Obs Conc %CV_1'!$C$23:$Q$78,13,FALSE) -> 0 | AD2: =VLOOKUP(D2,'Obs Conc_1'!$C$23:$Q$78,14,FALSE) -> OOR < | AE2: =VLOOKUP(D2,'Obs Conc %CV_1'!$C$23:$Q$78,14,FALSE) -> 0 | AF2: =VLOOKUP(D2,'Obs Conc_1'!$C$23:$Q$78,15,FALSE) -> OOR < | AG2: =VLOOKUP(D2,'Obs Conc %CV_1'!$C$23:$Q$78,15,FALSE) -> 0
A3: ADRECMO | B3: box 1 | C3: ADRECMO-01_SR_J3-J5 | D3: A002 | E3: serum | F3: =VLOOKUP(D3,'Obs Conc_1'!$C$23:$Q$78,2,FALSE) -> OOR < | G3: =VLOOKUP(D3,'Obs Conc %CV_1'!$C$23:$Q$78,2,FALSE) -> 0 | H3: =VLOOKUP(D3,'Obs Conc_1'!$C$23:$Q$78,3,FALSE) -> OOR < | I3: =VLOOKUP(D3,'Obs Conc %CV_1'!$C$23:$Q$78,3,FALSE) -> 0 | J3: =VLOOKUP(D3,'Obs Conc_1'!$C$23:$Q$78,4,FALSE) -> OOR < | K3: =VLOOKUP(D3,'Obs Conc %CV_1'!$C$23:$Q$78,4,FALSE) -> 0 | L3: =VLOOKUP(D3,'Obs Conc_1'!$C$23:$Q$78,5,FALSE) -> OOR < | M3: =VLOOKUP(D3,'Obs Conc %CV_1'!$C$23:$Q$78,5,FALSE) -> 0 | N3: =VLOOKUP(D3,'Obs Conc_1'!$C$23:$Q$78,6,FALSE) -> *2.50 | O3: =VLOOKUP(D3,'Obs Conc %CV_1'!$C$23:$Q$78,6,FALSE) -> 73.6 | P3: =VLOOKUP(D3,'Obs Conc_1'!$C$23:$Q$78,7,FALSE) -> 47.13 | Q3: =VLOOKUP(D3,'Obs Conc %CV_1'!$C$23:$Q$78,7,FALSE) -> 9.01 | R3: =VLOOKUP(D3,'Obs Conc_1'!$C$23:$Q$78,8,FALSE) -> 3.29 | S3: =VLOOKUP(D3,'Obs Conc %CV_1'!$C$23:$Q$78,8,FALSE) -> 7.48 | T3: =VLOOKUP(D3,'Obs Conc_1'!$C$23:$Q$78,9,FALSE) -> OOR < | U3: =VLOOKUP(D3,'Obs Conc %CV_1'!$C$23:$Q$78,9,FALSE) -> 0 | V3: =VLOOKUP(D3,'Obs Conc_1'!$C$23:$Q$78,10,FALSE) -> 313.34 | W3: =VLOOKUP(D3,'Obs Conc %CV_1'!$C$23:$Q$78,10,FALSE) -> 0.64 | X3: =VLOOKUP(D3,'Obs Conc_1'!$C$23:$Q$78,11,FALSE) -> OOR < | Y3: =VLOOKUP(D3,'Obs Conc %CV_1'!$C$23:$Q$78,11,FALSE) -> 0 | Z3: =VLOOKUP(D3,'Obs Conc_1'!$C$23:$Q$78,12,FALSE) -> OOR < | AA3: =VLOOKUP(D3,'Obs Conc %CV_1'!$C$23:$Q$78,12,FALSE) -> 0 | AB3: =VLOOKUP(D3,'Obs Conc_1'!$C$23:$Q$78,13,FALSE) -> OOR < | AC3: =VLOOKUP(D3,'Obs Conc %CV_1'!$C$23:$Q$78,13,FALSE) -> 0 | AD3: =VLOOKUP(D3,'Obs Conc_1'!$C$23:$Q$78,14,FALSE) -> OOR < | AE3: =VLOOKUP(D3,'Obs Conc %CV_1'!$C$23:$Q$78,14,FALSE) -> 0 | AF3: =VLOOKUP(D3,'Obs Conc_1'!$C$23:$Q$78,15,FALSE) -> OOR < | AG3: =VLOOKUP(D3,'Obs Conc %CV_1'!$C$23:$Q$78,15,FALSE) -> 0
A4: ADRECMO | B4: box 1 | C4: ADRECMO-01_SR_JS | D4: A003 | E4: serum | F4: =VLOOKUP(D4,'Obs Conc_1'!$C$23:$Q$78,2,FALSE) -> OOR < | G4: =VLOOKUP(D4,'Obs Conc %CV_1'!$C$23:$Q$78,2,FALSE) -> 0 | H4: =VLOOKUP(D4,'Obs Conc_1'!$C$23:$Q$78,3,FALSE) -> OOR < | I4: =VLOOKUP(D4,'Obs Conc %CV_1'!$C$23:$Q$78,3,FALSE) -> 0 | J4: =VLOOKUP(D4,'Obs Conc_1'!$C$23:$Q$78,4,FALSE) -> OOR < | K4: =VLOOKUP(D4,'Obs Conc %CV_1'!$C$23:$Q$78,4,FALSE) -> 0 | L4: =VLOOKUP(D4,'Obs Conc_1'!$C$23:$Q$78,5,FALSE) -> OOR < | M4: =VLOOKUP(D4,'Obs Conc %CV_1'!$C$23:$Q$78,5,FALSE) -> 0 | N4: =VLOOKUP(D4,'Obs Conc_1'!$C$23:$Q$78,6,FALSE) -> *0.01 | O4: =VLOOKUP(D4,'Obs Conc %CV_1'!$C$23:$Q$78,6,FALSE) -> 0 | P4: =VLOOKUP(D4,'Obs Conc_1'!$C$23:$Q$78,7,FALSE) -> 53.41 | Q4: =VLOOKUP(D4,'Obs Conc %CV_1'!$C$23:$Q$78,7,FALSE) -> 26.14 | R4: =VLOOKUP(D4,'Obs Conc_1'!$C$23:$Q$78,8,FALSE) -> 3.47 | S4: =VLOOKUP(D4,'Obs Conc %CV_1'!$C$23:$Q$78,8,FALSE) -> 31.95 | T4: =VLOOKUP(D4,'Obs Conc_1'!$C$23:$Q$78,9,FALSE) -> OOR < | U4: =VLOOKUP(D4,'Obs Conc %CV_1'!$C$23:$Q$78,9,FALSE) -> 0 | V4: =VLOOKUP(D4,'Obs Conc_1'!$C$23:$Q$78,10,FALSE) -> 379.9 | W4: =VLOOKUP(D4,'Obs Conc %CV_1'!$C$23:$Q$78,10,FALSE) -> 19.7 | X4: =VLOOKUP(D4,'Obs Conc_1'!$C$23:$Q$78,11,FALSE) -> OOR < | Y4: =VLOOKUP(D4,'Obs Conc %CV_1'!$C$23:$Q$78,11,FALSE) -> 0 | Z4: =VLOOKUP(D4,'Obs Conc_1'!$C$23:$Q$78,12,FALSE) -> OOR < | AA4: =VLOOKUP(D4,'Obs Conc %CV_1'!$C$23:$Q$78,12,FALSE) -> 0 | AB4: =VLOOKUP(D4,'Obs Conc_1'!$C$23:$Q$78,13,FALSE) -> OOR < | AC4: =VLOOKUP(D4,'Obs Conc %CV_1'!$C$23:$Q$78,13,FALSE) -> 0 | AD4: =VLOOKUP(D4,'Obs Conc_1'!$C$23:$Q$78,14,FALSE) -> OOR < | AE4: =VLOOKUP(D4,'Obs Conc %CV_1'!$C$23:$Q$78,14,FALSE) -> 0 | AF4: =VLOOKUP(D4,'Obs Conc_1'!$C$23:$Q$78,15,FALSE) -> OOR < | AG4: =VLOOKUP(D4,'Obs Conc %CV_1'!$C$23:$Q$78,15,FALSE) -> 0
A5: ADRECMO | B5: box 1 | C5: ADRECMO-02_SR_J0 | D5: A004 | E5: serum | F5: =VLOOKUP(D5,'Obs Conc_1'!$C$23:$Q$78,2,FALSE) -> OOR < | G5: =VLOOKUP(D5,'Obs Conc %CV_1'!$C$23:$Q$78,2,FALSE) -> 0 | H5: =VLOOKUP(D5,'Obs Conc_1'!$C$23:$Q$78,3,FALSE) -> OOR < | I5: =VLOOKUP(D5,'Obs Conc %CV_1'!$C$23:$Q$78,3,FALSE) -> 0 | J5: =VLOOKUP(D5,'Obs Conc_1'!$C$23:$Q$78,4,FALSE) -> OOR < | K5: =VLOOKUP(D5,'Obs Conc %CV_1'!$C$23:$Q$78,4,FALSE) -> 0 | L5: =VLOOKUP(D5,'Obs Conc_1'!$C$23:$Q$78,5,FALSE) -> OOR < | M5: =VLOOKUP(D5,'Obs Conc %CV_1'!$C$23:$Q$78,5,FALSE) -> 0 | N5: =VLOOKUP(D5,'Obs Conc_1'!$C$23:$Q$78,6,FALSE) -> *5.19 | O5: =VLOOKUP(D5,'Obs Conc %CV_1'!$C$23:$Q$78,6,FALSE) -> 0 | P5: =VLOOKUP(D5,'Obs Conc_1'!$C$23:$Q$78,7,FALSE) -> 416.67 | Q5: =VLOOKUP(D5,'Obs Conc %CV_1'!$C$23:$Q$78,7,FALSE) -> 5.37 | R5: =VLOOKUP(D5,'Obs Conc_1'!$C$23:$Q$78,8,FALSE) -> 87.29 | S5: =VLOOKUP(D5,'Obs Conc %CV_1'!$C$23:$Q$78,8,FALSE) -> 1.37 | T5: =VLOOKUP(D5,'Obs Conc_1'!$C$23:$Q$78,9,FALSE) -> 105.86 | U5: =VLOOKUP(D5,'Obs Conc %CV_1'!$C$23:$Q$78,9,FALSE) -> 4.04 | V5: =VLOOKUP(D5,'Obs Conc_1'!$C$23:$Q$78,10,FALSE) -> 660.73 | W5: =VLOOKUP(D5,'Obs Conc %CV_1'!$C$23:$Q$78,10,FALSE) -> 4.57 | X5: =VLOOKUP(D5,'Obs Conc_1'!$C$23:$Q$78,11,FALSE) -> OOR < | Y5: =VLOOKUP(D5,'Obs Conc %CV_1'!$C$23:$Q$78,11,FALSE) -> 0 | Z5: =VLOOKUP(D5,'Obs Conc_1'!$C$23:$Q$78,12,FALSE) -> OOR < | AA5: =VLOOKUP(D5,'Obs Conc %CV_1'!$C$23:$Q$78,12,FALSE) -> 0 | AB5: =VLOOKUP(D5,'Obs Conc_1'!$C$23:$Q$78,13,FALSE) -> OOR < | AC5: =VLOOKUP(D5,'Obs Conc %CV_1'!$C$23:$Q$78,13,FALSE) -> 0 | AD5: =VLOOKUP(D5,'Obs Conc_1'!$C$23:$Q$78,14,FALSE) -> OOR < | AE5: =VLOOKUP(D5,'Obs Conc %CV_1'!$C$23:$Q$78,14,FALSE) -> 0 | AF5: =VLOOKUP(D5,'Obs Conc_1'!$C$23:$Q$78,15,FALSE) -> OOR < | AG5: =VLOOKUP(D5,'Obs Conc %CV_1'!$C$23:$Q$78,15,FALSE) -> 0
A6: ADRECMO | B6: box 1 | C6: ADRECMO-02_SR_J3-J5 | D6: A005 | E6: serum | F6: =VLOOKUP(D6,'Obs Conc_1'!$C$23:$Q$78,2,FALSE) -> OOR < | G6: =VLOOKUP(D6,'Obs Conc %CV_1'!$C$23:$Q$78,2,FALSE) -> 0 | H6: =VLOOKUP(D6,'Obs Conc_1'!$C$23:$Q$78,3,FALSE) -> OOR < | I6: =VLOOKUP(D6,'Obs Conc %CV_1'!$C$23:$Q$78,3,FALSE) -> 0 | J6: =VLOOKUP(D6,'Obs Conc_1'!$C$23:$Q$78,4,FALSE) -> OOR < | K6: =VLOOKUP(D6,'Obs Conc %CV_1'!$C$23:$Q$78,4,FALSE) -> 0 | L6: =VLOOKUP(D6,'Obs Conc_1'!$C$23:$Q$78,5,FALSE) -> OOR < | M6: =VLOOKUP(D6,'Obs Conc %CV_1'!$C$23:$Q$78,5,FALSE) -> 0 | N6: =VLOOKUP(D6,'Obs Conc_1'!$C$23:$Q$78,6,FALSE) -> *6.56 | O6: =VLOOKUP(D6,'Obs Conc %CV_1'!$C$23:$Q$78,6,FALSE) -> 0 | P6: =VLOOKUP(D6,'Obs Conc_1'!$C$23:$Q$78,7,FALSE) -> 50.78 | Q6: =VLOOKUP(D6,'Obs Conc %CV_1'!$C$23:$Q$78,7,FALSE) -> 1.84 | R6: =VLOOKUP(D6,'Obs Conc_1'!$C$23:$Q$78,8,FALSE) -> 18.75 | S6: =VLOOKUP(D6,'Obs Conc %CV_1'!$C$23:$Q$78,8,FALSE) -> 12.99 | T6: =VLOOKUP(D6,'Obs Conc_1'!$C$23:$Q$78,9,FALSE) -> *1.52 | U6: =VLOOKUP(D6,'Obs Conc %CV_1'!$C$23:$Q$78,9,FALSE) -> 11.84 | V6: =VLOOKUP(D6,'Obs Conc_1'!$C$23:$Q$78,10,FALSE) -> 580.6 | W6: =VLOOKUP(D6,'Obs Conc %CV_1'!$C$23:$Q$78,10,FALSE) -> 9.12 | X6: =VLOOKUP(D6,'Obs Conc_1'!$C$23:$Q$78,11,FALSE) -> OOR < | Y6: =VLOOKUP(D6,'Obs Conc %CV_1'!$C$23:$Q$78,11,FALSE) -> 0 | Z6: =VLOOKUP(D6,'Obs Conc_1'!$C$23:$Q$78,12,FALSE) -> OOR < | AA6: =VLOOKUP(D6,'Obs Conc %CV_1'!$C$23:$Q$78,12,FALSE) -> 0 | AB6: =VLOOKUP(D6,'Obs Conc_1'!$C$23:$Q$78,13,FALSE) -> OOR < | AC6: =VLOOKUP(D6,'Obs Conc %CV_1'!$C$23:$Q$78,13,FALSE) -> 0 | AD6: =VLOOKUP(D6,'Obs Conc_1'!$C$23:$Q$78,14,FALSE) -> OOR < | AE6: =VLOOKUP(D6,'Obs Conc %CV_1'!$C$23:$Q$78,14,FALSE) -> 0 | AF6: =VLOOKUP(D6,'Obs Conc_1'!$C$23:$Q$78,15,FALSE) -> OOR < | AG6: =VLOOKUP(D6,'Obs Conc %CV_1'!$C$23:$Q$78,15,FALSE) -> 0
A7: ADRECMO | B7: box 1 | C7: ADRECMO-02_SR_JS | D7: A006 | E7: serum | F7: =VLOOKUP(D7,'Obs Conc_1'!$C$23:$Q$78,2,FALSE) -> OOR < | G7: =VLOOKUP(D7,'Obs Conc %CV_1'!$C$23:$Q$78,2,FALSE) -> 0 | H7: =VLOOKUP(D7,'Obs Conc_1'!$C$23:$Q$78,3,FALSE) -> OOR < | I7: =VLOOKUP(D7,'Obs Conc %CV_1'!$C$23:$Q$78,3,FALSE) -> 0 | J7: =VLOOKUP(D7,'Obs Conc_1'!$C$23:$Q$78,4,FALSE) -> OOR < | K7: =VLOOKUP(D7,'Obs Conc %CV_1'!$C$23:$Q$78,4,FALSE) -> 0 | L7: =VLOOKUP(D7,'Obs Conc_1'!$C$23:$Q$78,5,FALSE) -> OOR < | M7: =VLOOKUP(D7,'Obs Conc %CV_1'!$C$23:$Q$78,5,FALSE) -> 0 | N7: =VLOOKUP(D7,'Obs Conc_1'!$C$23:$Q$78,6,FALSE) -> *6.56 | O7: =VLOOKUP(D7,'Obs Conc %CV_1'!$C$23:$Q$78,6,FALSE) -> 59.21 | P7: =VLOOKUP(D7,'Obs Conc_1'!$C$23:$Q$78,7,FALSE) -> 55.37 | Q7: =VLOOKUP(D7,'Obs Conc %CV_1'!$C$23:$Q$78,7,FALSE) -> 13.35 | R7: =VLOOKUP(D7,'Obs Conc_1'!$C$23:$Q$78,8,FALSE) -> 22.31 | S7: =VLOOKUP(D7,'Obs Conc %CV_1'!$C$23:$Q$78,8,FALSE) -> 24.31 | T7: =VLOOKUP(D7,'Obs Conc_1'!$C$23:$Q$78,9,FALSE) -> 4.12 | U7: =VLOOKUP(D7,'Obs Conc %CV_1'!$C$23:$Q$78,9,FALSE) -> 25.17 | V7: =VLOOKUP(D7,'Obs Conc_1'!$C$23:$Q$78,10,FALSE) -> 655.39 | W7: =VLOOKUP(D7,'Obs Conc %CV_1'!$C$23:$Q$78,10,FALSE) -> 6.59 | X7: =VLOOKUP(D7,'Obs Conc_1'!$C$23:$Q$78,11,FALSE) -> OOR < | Y7: =VLOOKUP(D7,'Obs Conc %CV_1'!$C$23:$Q$78,11,FALSE) -> 0 | Z7: =VLOOKUP(D7,'Obs Conc_1'!$C$23:$Q$78,12,FALSE) -> OOR < | AA7: =VLOOKUP(D7,'Obs Conc %CV_1'!$C$23:$Q$78,12,FALSE) -> 0 | AB7: =VLOOKUP(D7,'Obs Conc_1'!$C$23:$Q$78,13,FALSE) -> OOR < | AC7: =VLOOKUP(D7,'Obs Conc %CV_1'!$C$23:$Q$78,13,FALSE) -> 0 | AD7: =VLOOKUP(D7,'Obs Conc_1'!$C$23:$Q$78,14,FALSE) -> OOR < | AE7: =VLOOKUP(D7,'Obs Conc %CV_1'!$C$23:$Q$78,14,FALSE) -> 0 | AF7: =VLOOKUP(D7,'Obs Conc_1'!$C$23:$Q$78,15,FALSE) -> OOR < | AG7: =VLOOKUP(D7,'Obs Conc %CV_1'!$C$23:$Q$78,15,FALSE) -> 0
A8: ADRECMO | B8: box 1 | C8: ADRECMO-03_SR_J0 | D8: A007 | E8: serum | F8: =VLOOKUP(D8,'Obs Conc_1'!$C$23:$Q$78,2,FALSE) -> OOR < | G8: =VLOOKUP(D8,'Obs Conc %CV_1'!$C$23:$Q$78,2,FALSE) -> 0 | H8: =VLOOKUP(D8,'Obs Conc_1'!$C$23:$Q$78,3,FALSE) -> OOR < | I8: =VLOOKUP(D8,'Obs Conc %CV_1'!$C$23:$Q$78,3,FALSE) -> 0 | J8: =VLOOKUP(D8,'Obs Conc_1'!$C$23:$Q$78,4,FALSE) -> OOR < | K8: =VLOOKUP(D8,'Obs Conc %CV_1'!$C$23:$Q$78,4,FALSE) -> 0 | L8: =VLOOKUP(D8,'Obs Conc_1'!$C$23:$Q$78,5,FALSE) -> OOR < | M8: =VLOOKUP(D8,'Obs Conc %CV_1'!$C$23:$Q$78,5,FALSE) -> 0 | N8: =VLOOKUP(D8,'Obs Conc_1'!$C$23:$Q$78,6,FALSE) -> *0.01 | O8: =VLOOKUP(D8,'Obs Conc %CV_1'!$C$23:$Q$78,6,FALSE) -> 0 | P8: =VLOOKUP(D8,'Obs Conc_1'!$C$23:$Q$78,7,FALSE) -> 90.99 | Q8: =VLOOKUP(D8,'Obs Conc %CV_1'!$C$23:$Q$78,7,FALSE) -> 6.18 | R8: =VLOOKUP(D8,'Obs Conc_1'!$C$23:$Q$78,8,FALSE) -> 2.81 | S8: =VLOOKUP(D8,'Obs Conc %CV_1'!$C$23:$Q$78,8,FALSE) -> 19.94 | T8: =VLOOKUP(D8,'Obs Conc_1'!$C$23:$Q$78,9,FALSE) -> 10.4 | U8: =VLOOKUP(D8,'Obs Conc %CV_1'!$C$23:$Q$78,9,FALSE) -> 17.37 | V8: =VLOOKUP(D8,'Obs Conc_1'!$C$23:$Q$78,10,FALSE) -> 423.87 | W8: =VLOOKUP(D8,'Obs Conc %CV_1'!$C$23:$Q$78,10,FALSE) -> 7.74 | X8: =VLOOKUP(D8,'Obs Conc_1'!$C$23:$Q$78,11,FALSE) -> OOR < | Y8: =VLOOKUP(D8,'Obs Conc %CV_1'!$C$23:$Q$78,11,FALSE) -> 0 | Z8: =VLOOKUP(D8,'Obs Conc_1'!$C$23:$Q$78,12,FALSE) -> OOR < | AA8: =VLOOKUP(D8,'Obs Conc %CV_1'!$C$23:$Q$78,12,FALSE) -> 0 | AB8: =VLOOKUP(D8,'Obs Conc_1'!$C$23:$Q$78,13,FALSE) -> OOR < | AC8: =VLOOKUP(D8,'Obs Conc %CV_1'!$C$23:$Q$78,13,FALSE) -> 0 | AD8: =VLOOKUP(D8,'Obs Conc_1'!$C$23:$Q$78,14,FALSE) -> OOR < | AE8: =VLOOKUP(D8,'Obs Conc %CV_1'!$C$23:$Q$78,14,FALSE) -> 0 | AF8: =VLOOKUP(D8,'Obs Conc_1'!$C$23:$Q$78,15,FALSE) -> OOR < | AG8: =VLOOKUP(D8,'Obs Conc %CV_1'!$C$23:$Q$78,15,FALSE) -> 0
A9: ADRECMO | B9: box 1 | C9: ADRECMO-03_SR_J3 | D9: A008 | E9: serum | F9: =VLOOKUP(D9,'Obs Conc_1'!$C$23:$Q$78,2,FALSE) -> OOR < | G9: =VLOOKUP(D9,'Obs Conc %CV_1'!$C$23:$Q$78,2,FALSE) -> 0 | H9: =VLOOKUP(D9,'Obs Conc_1'!$C$23:$Q$78,3,FALSE) -> OOR < | I9: =VLOOKUP(D9,'Obs Conc %CV_1'!$C$23:$Q$78,3,FALSE) -> 0 | J9: =VLOOKUP(D9,'Obs Conc_1'!$C$23:$Q$78,4,FALSE) -> OOR < | K9: =VLOOKUP(D9,'Obs Conc %CV_1'!$C$23:$Q$78,4,FALSE) -> 0 | L9: =VLOOKUP(D9,'Obs Conc_1'!$C$23:$Q$78,5,FALSE) -> OOR < | M9: =VLOOKUP(D9,'Obs Conc %CV_1'!$C$23:$Q$78,5,FALSE) -> 0 | N9: =VLOOKUP(D9,'Obs Conc_1'!$C$23:$Q$78,6,FALSE) -> *3.83 | O9: =VLOOKUP(D9,'Obs Conc %CV_1'!$C$23:$Q$78,6,FALSE) -> 97.42 | P9: =VLOOKUP(D9,'Obs Conc_1'!$C$23:$Q$78,7,FALSE) -> 59.92 | Q9: =VLOOKUP(D9,'Obs Conc %CV_1'!$C$23:$Q$78,7,FALSE) -> 7.63 | R9: =VLOOKUP(D9,'Obs Conc_1'!$C$23:$Q$78,8,FALSE) -> 2.5 | S9: =VLOOKUP(D9,'Obs Conc %CV_1'!$C$23:$Q$78,8,FALSE) -> 20.07 | T9: =VLOOKUP(D9,'Obs Conc_1'!$C$23:$Q$78,9,FALSE) -> OOR < | U9: =VLOOKUP(D9,'Obs Conc %CV_1'!$C$23:$Q$78,9,FALSE) -> 0 | V9: =VLOOKUP(D9,'Obs Conc_1'!$C$23:$Q$78,10,FALSE) -> 416.77 | W9: =VLOOKUP(D9,'Obs Conc %CV_1'!$C$23:$Q$78,10,FALSE) -> 1.61 | X9: =VLOOKUP(D9,'Obs Conc_1'!$C$23:$Q$78,11,FALSE) -> OOR < | Y9: =VLOOKUP(D9,'Obs Conc %CV_1'!$C$23:$Q$78,11,FALSE) -> 0 | Z9: =VLOOKUP(D9,'Obs Conc_1'!$C$23:$Q$78,12,FALSE) -> OOR < | AA9: =VLOOKUP(D9,'Obs Conc %CV_1'!$C$23:$Q$78,12,FALSE) -> 0 | AB9: =VLOOKUP(D9,'Obs Conc_1'!$C$23:$Q$78,13,FALSE) -> OOR < | AC9: =VLOOKUP(D9,'Obs Conc %CV_1'!$C$23:$Q$78,13,FALSE) -> 0 | AD9: =VLOOKUP(D9,'Obs Conc_1'!$C$23:$Q$78,14,FALSE) -> OOR < | AE9: =VLOOKUP(D9,'Obs Conc %CV_1'!$C$23:$Q$78,14,FALSE) -> 0 | AF9: =VLOOKUP(D9,'Obs Conc_1'!$C$23:$Q$78,15,FALSE) -> OOR < | AG9: =VLOOKUP(D9,'Obs Conc %CV_1'!$C$23:$Q$78,15,FALSE) -> 0
A10: ADRECMO | B10: box 1 | C10: ADRECMO-03_SR_JS | D10: A009 | E10: serum | F10: =VLOOKUP(D10,'Obs Conc_1'!$C$23:$Q$78,2,FALSE) -> OOR < | G10: =VLOOKUP(D10,'Obs Conc %CV_1'!$C$23:$Q$78,2,FALSE) -> 0 | H10: =VLOOKUP(D10,'Obs Conc_1'!$C$23:$Q$78,3,FALSE) -> OOR < | I10: =VLOOKUP(D10,'Obs Conc %CV_1'!$C$23:$Q$78,3,FALSE) -> 0 | J10: =VLOOKUP(D10,'Obs Conc_1'!$C$23:$Q$78,4,FALSE) -> OOR < | K10: =VLOOKUP(D10,'Obs Conc %CV_1'!$C$23:$Q$78,4,FALSE) -> 0 | L10: =VLOOKUP(D10,'Obs Conc_1'!$C$23:$Q$78,5,FALSE) -> OOR < | M10: =VLOOKUP(D10,'Obs Conc %CV_1'!$C$23:$Q$78,5,FALSE) -> 0 | N10: =VLOOKUP(D10,'Obs Conc_1'!$C$23:$Q$78,6,FALSE) -> OOR < | O10: =VLOOKUP(D10,'Obs Conc %CV_1'!$C$23:$Q$78,6,FALSE) -> 0 | P10: =VLOOKUP(D10,'Obs Conc_1'!$C$23:$Q$78,7,FALSE) -> 42.76 | Q10: =VLOOKUP(D10,'Obs Conc %CV_1'!$C$23:$Q$78,7,FALSE) -> 0 | R10: =VLOOKUP(D10,'Obs Conc_1'!$C$23:$Q$78,8,FALSE) -> 5.77 | S10: =VLOOKUP(D10,'Obs Conc %CV_1'!$C$23:$Q$78,8,FALSE) -> 0 | T10: =VLOOKUP(D10,'Obs Conc_1'!$C$23:$Q$78,9,FALSE) -> OOR < | U10: =VLOOKUP(D10,'Obs Conc %CV_1'!$C$23:$Q$78,9,FALSE) -> 0 | V10: =VLOOKUP(D10,'Obs Conc_1'!$C$23:$Q$78,10,FALSE) -> 613.32 | W10: =VLOOKUP(D10,'Obs Conc %CV_1'!$C$23:$Q$78,10,FALSE) -> 0 | X10: =VLOOKUP(D10,'Obs Conc_1'!$C$23:$Q$78,11,FALSE) -> OOR < | Y10: =VLOOKUP(D10,'Obs Conc %CV_1'!$C$23:$Q$78,11,FALSE) -> 0 | Z10: =VLOOKUP(D10,'Obs Conc_1'!$C$23:$Q$78,12,FALSE) -> OOR < | AA10: =VLOOKUP(D10,'Obs Conc %CV_1'!$C$23:$Q$78,12,FALSE) -> 0 | AB10: =VLOOKUP(D10,'Obs Conc_1'!$C$23:$Q$78,13,FALSE) -> OOR < | AC10: =VLOOKUP(D10,'Obs Conc %CV_1'!$C$23:$Q$78,13,FALSE) -> 0 | AD10: =VLOOKUP(D10,'Obs Conc_1'!$C$23:$Q$78,14,FALSE) -> OOR < | AE10: =VLOOKUP(D10,'Obs Conc %CV_1'!$C$23:$Q$78,14,FALSE) -> 0 | AF10: =VLOOKUP(D10,'Obs Conc_1'!$C$23:$Q$78,15,FALSE) -> OOR < | AG10: =VLOOKUP(D10,'Obs Conc %CV_1'!$C$23:$Q$78,15,FALSE) -> 0
A11: ADRECMO | B11: box 1 | C11: ADRECMO-04_SR_J0 | D11: A010 | E11: serum | F11: =VLOOKUP(D11,'Obs Conc_1'!$C$23:$Q$78,2,FALSE) -> OOR < | G11: =VLOOKUP(D11,'Obs Conc %CV_1'!$C$23:$Q$78,2,FALSE) -> 0 | H11: =VLOOKUP(D11,'Obs Conc_1'!$C$23:$Q$78,3,FALSE) -> OOR < | I11: =VLOOKUP(D11,'Obs Conc %CV_1'!$C$23:$Q$78,3,FALSE) -> 0 | J11: =VLOOKUP(D11,'Obs Conc_1'!$C$23:$Q$78,4,FALSE) -> OOR < | K11: =VLOOKUP(D11,'Obs Conc %CV_1'!$C$23:$Q$78,4,FALSE) -> 0 | L11: =VLOOKUP(D11,'Obs Conc_1'!$C$23:$Q$78,5,FALSE) -> OOR < | M11: =VLOOKUP(D11,'Obs Conc %CV_1'!$C$23:$Q$78,5,FALSE) -> 0 | N11: =VLOOKUP(D11,'Obs Conc_1'!$C$23:$Q$78,6,FALSE) -> 9.36 | O11: =VLOOKUP(D11,'Obs Conc %CV_1'!$C$23:$Q$78,6,FALSE) -> 0 | P11: =VLOOKUP(D11,'Obs Conc_1'!$C$23:$Q$78,7,FALSE) -> 347.38 | Q11: =VLOOKUP(D11,'Obs Conc %CV_1'!$C$23:$Q$78,7,FALSE) -> 0 | R11: =VLOOKUP(D11,'Obs Conc_1'!$C$23:$Q$78,8,FALSE) -> 47.59 | S11: =VLOOKUP(D11,'Obs Conc %CV_1'!$C$23:$Q$78,8,FALSE) -> 0 | T11: =VLOOKUP(D11,'Obs Conc_1'!$C$23:$Q$78,9,FALSE) -> 17.34 | U11: =VLOOKUP(D11,'Obs Conc %CV_1'!$C$23:$Q$78,9,FALSE) -> 0 | V11: =VLOOKUP(D11,'Obs Conc_1'!$C$23:$Q$78,10,FALSE) -> 308.15 | W11: =VLOOKUP(D11,'Obs Conc %CV_1'!$C$23:$Q$78,10,FALSE) -> 0 | X11: =VLOOKUP(D11,'Obs Conc_1'!$C$23:$Q$78,11,FALSE) -> OOR < | Y11: =VLOOKUP(D11,'Obs Conc %CV_1'!$C$23:$Q$78,11,FALSE) -> 0 | Z11: =VLOOKUP(D11,'Obs Conc_1'!$C$23:$Q$78,12,FALSE) -> OOR < | AA11: =VLOOKUP(D11,'Obs Conc %CV_1'!$C$23:$Q$78,12,FALSE) -> 0 | AB11: =VLOOKUP(D11,'Obs Conc_1'!$C$23:$Q$78,13,FALSE) -> OOR < | AC11: =VLOOKUP(D11,'Obs Conc %CV_1'!$C$23:$Q$78,13,FALSE) -> 0 | AD11: =VLOOKUP(D11,'Obs Conc_1'!$C$23:$Q$78,14,FALSE) -> OOR < | AE11: =VLOOKUP(D11,'Obs Conc %CV_1'!$C$23:$Q$78,14,FALSE) -> 0 | AF11: =VLOOKUP(D11,'Obs Conc_1'!$C$23:$Q$78,15,FALSE) -> OOR < | AG11: =VLOOKUP(D11,'Obs Conc %CV_1'!$C$23:$Q$78,15,FALSE) -> 0
A12: ADRECMO | B12: box 1 | C12: ADRECMO-04_SR_J3 | D12: A011 | E12: serum | F12: =VLOOKUP(D12,'Obs Conc_1'!$C$23:$Q$78,2,FALSE) -> OOR < | G12: =VLOOKUP(D12,'Obs Conc %CV_1'!$C$23:$Q$78,2,FALSE) -> 0 | H12: =VLOOKUP(D12,'Obs Conc_1'!$C$23:$Q$78,3,FALSE) -> OOR < | I12: =VLOOKUP(D12,'Obs Conc %CV_1'!$C$23:$Q$78,3,FALSE) -> 0 | J12: =VLOOKUP(D12,'Obs Conc_1'!$C$23:$Q$78,4,FALSE) -> OOR < | K12: =VLOOKUP(D12,'Obs Conc %CV_1'!$C$23:$Q$78,4,FALSE) -> 0 | L12: =VLOOKUP(D12,'Obs Conc_1'!$C$23:$Q$78,5,FALSE) -> OOR < | M12: =VLOOKUP(D12,'Obs Conc %CV_1'!$C$23:$Q$78,5,FALSE) -> 0 | N12: =VLOOKUP(D12,'Obs Conc_1'!$C$23:$Q$78,6,FALSE) -> OOR < | O12: =VLOOKUP(D12,'Obs Conc %CV_1'!$C$23:$Q$78,6,FALSE) -> 0 | P12: =VLOOKUP(D12,'Obs Conc_1'!$C$23:$Q$78,7,FALSE) -> 13.34 | Q12: =VLOOKUP(D12,'Obs Conc %CV_1'!$C$23:$Q$78,7,FALSE) -> 0 | R12: =VLOOKUP(D12,'Obs Conc_1'!$C$23:$Q$78,8,FALSE) -> *2.06 | S12: =VLOOKUP(D12,'Obs Conc %CV_1'!$C$23:$Q$78,8,FALSE) -> 0 | T12: =VLOOKUP(D12,'Obs Conc_1'!$C$23:$Q$78,9,FALSE) -> OOR < | U12: =VLOOKUP(D12,'Obs Conc %CV_1'!$C$23:$Q$78,9,FALSE) -> 0 | V12: =VLOOKUP(D12,'Obs Conc_1'!$C$23:$Q$78,10,FALSE) -> 267.51 | W12: =VLOOKUP(D12,'Obs Conc %CV_1'!$C$23:$Q$78,10,FALSE) -> 0 | X12: =VLOOKUP(D12,'Obs Conc_1'!$C$23:$Q$78,11,FALSE) -> OOR < | Y12: =VLOOKUP(D12,'Obs Conc %CV_1'!$C$23:$Q$78,11,FALSE) -> 0 | Z12: =VLOOKUP(D12,'Obs Conc_1'!$C$23:$Q$78,12,FALSE) -> OOR < | AA12: =VLOOKUP(D12,'Obs Conc %CV_1'!$C$23:$Q$78,12,FALSE) -> 0 | AB12: =VLOOKUP(D12,'Obs Conc_1'!$C$23:$Q$78,13,FALSE) -> OOR < | AC12: =VLOOKUP(D12,'Obs Conc %CV_1'!$C$23:$Q$78,13,FALSE) -> 0 | AD12: =VLOOKUP(D12,'Obs Conc_1'!$C$23:$Q$78,14,FALSE) -> OOR < | AE12: =VLOOKUP(D12,'Obs Conc %CV_1'!$C$23:$Q$78,14,FALSE) -> 0 | AF12: =VLOOKUP(D12,'Obs Conc_1'!$C$23:$Q$78,15,FALSE) -> OOR < | AG12: =VLOOKUP(D12,'Obs Conc %CV_1'!$C$23:$Q$78,15,FALSE) -> 0
A13: ADRECMO | B13: box 1 | C13: ADRECMO-04_SR_JS | D13: A012 | E13: serum | F13: =VLOOKUP(D13,'Obs Conc_1'!$C$23:$Q$78,2,FALSE) -> OOR < | G13: =VLOOKUP(D13,'Obs Conc %CV_1'!$C$23:$Q$78,2,FALSE) -> 0 | H13: =VLOOKUP(D13,'Obs Conc_1'!$C$23:$Q$78,3,FALSE) -> OOR < | I13: =VLOOKUP(D13,'Obs Conc %CV_1'!$C$23:$Q$78,3,FALSE) -> 0 | J13: =VLOOKUP(D13,'Obs Conc_1'!$C$23:$Q$78,4,FALSE) -> OOR < | K13: =VLOOKUP(D13,'Obs Conc %CV_1'!$C$23:$Q$78,4,FALSE) -> 0 | L13: =VLOOKUP(D13,'Obs Conc_1'!$C$23:$Q$78,5,FALSE) -> OOR < | M13: =VLOOKUP(D13,'Obs Conc %CV_1'!$C$23:$Q$78,5,FALSE) -> 0 | N13: =VLOOKUP(D13,'Obs Conc_1'!$C$23:$Q$78,6,FALSE) -> *1.21 | O13: =VLOOKUP(D13,'Obs Conc %CV_1'!$C$23:$Q$78,6,FALSE) -> 0 | P13: =VLOOKUP(D13,'Obs Conc_1'!$C$23:$Q$78,7,FALSE) -> 8.49 | Q13: =VLOOKUP(D13,'Obs Conc %CV_1'!$C$23:$Q$78,7,FALSE) -> 0 | R13: =VLOOKUP(D13,'Obs Conc_1'!$C$23:$Q$78,8,FALSE) -> 8.1 | S13: =VLOOKUP(D13,'Obs Conc %CV_1'!$C$23:$Q$78,8,FALSE) -> 0 | T13: =VLOOKUP(D13,'Obs Conc_1'!$C$23:$Q$78,9,FALSE) -> OOR < | U13: =VLOOKUP(D13,'Obs Conc %CV_1'!$C$23:$Q$78,9,FALSE) -> 0 | V13: =VLOOKUP(D13,'Obs Conc_1'!$C$23:$Q$78,10,FALSE) -> 327.98 | W13: =VLOOKUP(D13,'Obs Conc %CV_1'!$C$23:$Q$78,10,FALSE) -> 0 | X13: =VLOOKUP(D13,'Obs Conc_1'!$C$23:$Q$78,11,FALSE) -> OOR < | Y13: =VLOOKUP(D13,'Obs Conc %CV_1'!$C$23:$Q$78,11,FALSE) -> 0 | Z13: =VLOOKUP(D13,'Obs Conc_1'!$C$23:$Q$78,12,FALSE) -> OOR < | AA13: =VLOOKUP(D13,'Obs Conc %CV_1'!$C$23:$Q$78,12,FALSE) -> 0 | AB13: =VLOOKUP(D13,'Obs Conc_1'!$C$23:$Q$78,13,FALSE) -> OOR < | AC13: =VLOOKUP(D13,'Obs Conc %CV_1'!$C$23:$Q$78,13,FALSE) -> 0 | AD13: =VLOOKUP(D13,'Obs Conc_1'!$C$23:$Q$78,14,FALSE) -> OOR < | AE13: =VLOOKUP(D13,'Obs Conc %CV_1'!$C$23:$Q$78,14,FALSE) -> 0 | AF13: =VLOOKUP(D13,'Obs Conc_1'!$C$23:$Q$78,15,FALSE) -> OOR < | AG13: =VLOOKUP(D13,'Obs Conc %CV_1'!$C$23:$Q$78,15,FALSE) -> 0
... A57: ADRECMO | B57: box 1 | C57: ADRECMO-25_SR_JS | D57: A056 | E57: serum | F57: =VLOOKUP(D57,'Obs Conc_1'!$C$23:$Q$78,2,FALSE) -> *7.54 | G57: =VLOOKUP(D57,'Obs Conc %CV_1'!$C$23:$Q$78,2,FALSE) -> 25.85 | H57: =VLOOKUP(D57,'Obs Conc_1'!$C$23:$Q$78,3,FALSE) -> OOR < | I57: =VLOOKUP(D57,'Obs Conc %CV_1'!$C$23:$Q$78,3,FALSE) -> 0 | J57: =VLOOKUP(D57,'Obs Conc_1'!$C$23:$Q$78,4,FALSE) -> OOR < | K57: =VLOOKUP(D57,'Obs Conc %CV_1'!$C$23:$Q$78,4,FALSE) -> 0 | L57: =VLOOKUP(D57,'Obs Conc_1'!$C$23:$Q$78,5,FALSE) -> OOR < | M57: =VLOOKUP(D57,'Obs Conc %CV_1'!$C$23:$Q$78,5,FALSE) -> 0 | N57: =VLOOKUP(D57,'Obs Conc_1'!$C$23:$Q$78,6,FALSE) -> OOR < | O57: =VLOOKUP(D57,'Obs Conc %CV_1'!$C$23:$Q$78,6,FALSE) -> 0 | P57: =VLOOKUP(D57,'Obs Conc_1'!$C$23:$Q$78,7,FALSE) -> 34.9 | Q57: =VLOOKUP(D57,'Obs Conc %CV_1'!$C$23:$Q$78,7,FALSE) -> 4.22 | R57: =VLOOKUP(D57,'Obs Conc_1'!$C$23:$Q$78,8,FALSE) -> 146.77 | S57: =VLOOKUP(D57,'Obs Conc %CV_1'!$C$23:$Q$78,8,FALSE) -> 13.31 | T57: =VLOOKUP(D57,'Obs Conc_1'!$C$23:$Q$78,9,FALSE) -> OOR < | U57: =VLOOKUP(D57,'Obs Conc %CV_1'!$C$23:$Q$78,9,FALSE) -> 0 | V57: =VLOOKUP(D57,'Obs Conc_1'!$C$23:$Q$78,10,FALSE) -> 693.32 | W57: =VLOOKUP(D57,'Obs Conc %CV_1'!$C$23:$Q$78,10,FALSE) -> 13.22 | X57: =VLOOKUP(D57,'Obs Conc_1'!$C$23:$Q$78,11,FALSE) -> OOR < | Y57: =VLOOKUP(D57,'Obs Conc %CV_1'!$C$23:$Q$78,11,FALSE) -> 0 | Z57: =VLOOKUP(D57,'Obs Conc_1'!$C$23:$Q$78,12,FALSE) -> OOR < | AA57: =VLOOKUP(D57,'Obs Conc %CV_1'!$C$23:$Q$78,12,FALSE) -> 0 | AB57: =VLOOKUP(D57,'Obs Conc_1'!$C$23:$Q$78,13,FALSE) -> OOR < | AC57: =VLOOKUP(D57,'Obs Conc %CV_1'!$C$23:$Q$78,13,FALSE) -> 0 | AD57: =VLOOKUP(D57,'Obs Conc_1'!$C$23:$Q$78,14,FALSE) -> OOR < | AE57: =VLOOKUP(D57,'Obs Conc %CV_1'!$C$23:$Q$78,14,FALSE) -> 0 | AF57: =VLOOKUP(D57,'Obs Conc_1'!$C$23:$Q$78,15,FALSE) -> OOR < | AG57: =VLOOKUP(D57,'Obs Conc %CV_1'!$C$23:$Q$78,15,FALSE) -> 0
A58: ADRECMO | B58: box 1 | C58: ADRECMO-26_SR_J0 | D58: A057 | E58: serum | F58: =VLOOKUP(D58,'Obs Conc_2'!$C$23:$Q$78,2,FALSE) -> OOR < | G58: =VLOOKUP(D58,'Obs Conc %CV_2'!$C$23:$Q$78,2,FALSE) -> 0 | H58: =VLOOKUP(F58,'Obs Conc_2'!$E$23:$S$78,3,FALSE) -> OOR < | I58: =VLOOKUP(D58,'Obs Conc %CV_2'!$C$23:$Q$78,3,FALSE) -> 0 | J58: =VLOOKUP(D58,'Obs Conc_2'!$C$23:$Q$78,4,FALSE) -> OOR < | K58: =VLOOKUP(D58,'Obs Conc %CV_2'!$C$23:$Q$78,4,FALSE) -> 0 | L58: =VLOOKUP(D58,'Obs Conc_2'!$C$23:$Q$78,5,FALSE) -> OOR < | M58: =VLOOKUP(D58,'Obs Conc %CV_2'!$C$23:$Q$78,5,FALSE) -> 0 | N58: =VLOOKUP(D58,'Obs Conc_2'!$C$23:$Q$78,6,FALSE) -> OOR < | O58: =VLOOKUP(D58,'Obs Conc %CV_2'!$C$23:$Q$78,6,FALSE) -> 0 | P58: =VLOOKUP(D58,'Obs Conc_2'!$C$23:$Q$78,7,FALSE) -> 58.28 | Q58: =VLOOKUP(D58,'Obs Conc %CV_2'!$C$23:$Q$78,7,FALSE) -> 5.79 | R58: =VLOOKUP(D58,'Obs Conc_2'!$C$23:$Q$78,8,FALSE) -> 3.8 | S58: =VLOOKUP(D58,'Obs Conc %CV_2'!$C$23:$Q$78,8,FALSE) -> 36.38 | T58: =VLOOKUP(D58,'Obs Conc_2'!$C$23:$Q$78,9,FALSE) -> OOR < | U58: =VLOOKUP(D58,'Obs Conc %CV_2'!$C$23:$Q$78,9,FALSE) -> 0 | V58: =VLOOKUP(D58,'Obs Conc_2'!$C$23:$Q$78,10,FALSE) -> 470.06 | W58: =VLOOKUP(D58,'Obs Conc %CV_2'!$C$23:$Q$78,10,FALSE) -> 6.33 | X58: =VLOOKUP(D58,'Obs Conc_2'!$C$23:$Q$78,11,FALSE) -> OOR < | Y58: =VLOOKUP(D58,'Obs Conc %CV_2'!$C$23:$Q$78,11,FALSE) -> 0 | Z58: =VLOOKUP(D58,'Obs Conc_2'!$C$23:$Q$78,12,FALSE) -> OOR < | AA58: =VLOOKUP(D58,'Obs Conc %CV_2'!$C$23:$Q$78,12,FALSE) -> 0 | AB58: =VLOOKUP(D58,'Obs Conc_2'!$C$23:$Q$78,13,FALSE) -> OOR < | AC58: =VLOOKUP(D58,'Obs Conc %CV_2'!$C$23:$Q$78,13,FALSE) -> 0 | AD58: =VLOOKUP(D58,'Obs Conc_2'!$C$23:$Q$78,14,FALSE) -> OOR < | AE58: =VLOOKUP(D58,'Obs Conc %CV_2'!$C$23:$Q$78,14,FALSE) -> 0 | AF58: =VLOOKUP(D58,'Obs Conc_2'!$C$23:$Q$78,15,FALSE) -> OOR < | AG58: =VLOOKUP(D58,'Obs Conc %CV_2'!$C$23:$Q$78,15,FALSE) -> 0
A59: ADRECMO | B59: box 1 | C59: ADRECMO-26_SR_J3 | D59: A058 | E59: serum | F59: =VLOOKUP(D59,'Obs Conc_2'!$C$23:$Q$78,2,FALSE) -> OOR < | G59: =VLOOKUP(D59,'Obs Conc %CV_2'!$C$23:$Q$78,2,FALSE) -> 0 | H59: =VLOOKUP(F59,'Obs Conc_2'!$E$23:$S$78,3,FALSE) -> OOR < | I59: =VLOOKUP(D59,'Obs Conc %CV_2'!$C$23:$Q$78,3,FALSE) -> 0 | J59: =VLOOKUP(D59,'Obs Conc_2'!$C$23:$Q$78,4,FALSE) -> OOR < | K59: =VLOOKUP(D59,'Obs Conc %CV_2'!$C$23:$Q$78,4,FALSE) -> 0 | L59: =VLOOKUP(D59,'Obs Conc_2'!$C$23:$Q$78,5,FALSE) -> OOR < | M59: =VLOOKUP(D59,'Obs Conc %CV_2'!$C$23:$Q$78,5,FALSE) -> 0 | N59: =VLOOKUP(D59,'Obs Conc_2'!$C$23:$Q$78,6,FALSE) -> OOR < | O59: =VLOOKUP(D59,'Obs Conc %CV_2'!$C$23:$Q$78,6,FALSE) -> 0 | P59: =VLOOKUP(D59,'Obs Conc_2'!$C$23:$Q$78,7,FALSE) -> 62.01 | Q59: =VLOOKUP(D59,'Obs Conc %CV_2'!$C$23:$Q$78,7,FALSE) -> 15.42 | R59: =VLOOKUP(D59,'Obs Conc_2'!$C$23:$Q$78,8,FALSE) -> 3.06 | S59: =VLOOKUP(D59,'Obs Conc %CV_2'!$C$23:$Q$78,8,FALSE) -> 61.68 | T59: =VLOOKUP(D59,'Obs Conc_2'!$C$23:$Q$78,9,FALSE) -> OOR < | U59: =VLOOKUP(D59,'Obs Conc %CV_2'!$C$23:$Q$78,9,FALSE) -> 0 | V59: =VLOOKUP(D59,'Obs Conc_2'!$C$23:$Q$78,10,FALSE) -> 506.1 | W59: =VLOOKUP(D59,'Obs Conc %CV_2'!$C$23:$Q$78,10,FALSE) -> 5.5 | X59: =VLOOKUP(D59,'Obs Conc_2'!$C$23:$Q$78,11,FALSE) -> OOR < | Y59: =VLOOKUP(D59,'Obs Conc %CV_2'!$C$23:$Q$78,11,FALSE) -> 0 | Z59: =VLOOKUP(D59,'Obs Conc_2'!$C$23:$Q$78,12,FALSE) -> OOR < | AA59: =VLOOKUP(D59,'Obs Conc %CV_2'!$C$23:$Q$78,12,FALSE) -> 0 | AB59: =VLOOKUP(D59,'Obs Conc_2'!$C$23:$Q$78,13,FALSE) -> OOR < | AC59: =VLOOKUP(D59,'Obs Conc %CV_2'!$C$23:$Q$78,13,FALSE) -> 0 | AD59: =VLOOKUP(D59,'Obs Conc_2'!$C$23:$Q$78,14,FALSE) -> OOR < | AE59: =VLOOKUP(D59,'Obs Conc %CV_2'!$C$23:$Q$78,14,FALSE) -> 0 | AF59: =VLOOKUP(D59,'Obs Conc_2'!$C$23:$Q$78,15,FALSE) -> OOR < | AG59: =VLOOKUP(D59,'Obs Conc %CV_2'!$C$23:$Q$78,15,FALSE) -> 0
A60: ADRECMO | B60: box 1 | C60: ADRECMO-26_SR_JS | D60: A059 | E60: serum | F60: =VLOOKUP(D60,'Obs Conc_2'!$C$23:$Q$78,2,FALSE) -> OOR < | G60: =VLOOKUP(D60,'Obs Conc %CV_2'!$C$23:$Q$78,2,FALSE) -> 0 | H60: =VLOOKUP(F60,'Obs Conc_2'!$E$23:$S$78,3,FALSE) -> OOR < | I60: =VLOOKUP(D60,'Obs Conc %CV_2'!$C$23:$Q$78,3,FALSE) -> 0 | J60: =VLOOKUP(D60,'Obs Conc_2'!$C$23:$Q$78,4,FALSE) -> OOR < | K60: =VLOOKUP(D60,'Obs Conc %CV_2'!$C$23:$Q$78,4,FALSE) -> 0 | L60: =VLOOKUP(D60,'Obs Conc_2'!$C$23:$Q$78,5,FALSE) -> OOR < | M60: =VLOOKUP(D60,'Obs Conc %CV_2'!$C$23:$Q$78,5,FALSE) -> 0 | N60: =VLOOKUP(D60,'Obs Conc_2'!$C$23:$Q$78,6,FALSE) -> OOR < | O60: =VLOOKUP(D60,'Obs Conc %CV_2'!$C$23:$Q$78,6,FALSE) -> 0 | P60: =VLOOKUP(D60,'Obs Conc_2'!$C$23:$Q$78,7,FALSE) -> 16.93 | Q60: =VLOOKUP(D60,'Obs Conc %CV_2'!$C$23:$Q$78,7,FALSE) -> 0 | R60: =VLOOKUP(D60,'Obs Conc_2'!$C$23:$Q$78,8,FALSE) -> 4.34 | S60: =VLOOKUP(D60,'Obs Conc %CV_2'!$C$23:$Q$78,8,FALSE) -> 40.59 | T60: =VLOOKUP(D60,'Obs Conc_2'!$C$23:$Q$78,9,FALSE) -> OOR < | U60: =VLOOKUP(D60,'Obs Conc %CV_2'!$C$23:$Q$78,9,FALSE) -> 0 | V60: =VLOOKUP(D60,'Obs Conc_2'!$C$23:$Q$78,10,FALSE) -> 695.43 | W60: =VLOOKUP(D60,'Obs Conc %CV_2'!$C$23:$Q$78,10,FALSE) -> 3.2 | X60: =VLOOKUP(D60,'Obs Conc_2'!$C$23:$Q$78,11,FALSE) -> OOR < | Y60: =VLOOKUP(D60,'Obs Conc %CV_2'!$C$23:$Q$78,11,FALSE) -> 0 | Z60: =VLOOKUP(D60,'Obs Conc_2'!$C$23:$Q$78,12,FALSE) -> OOR < | AA60: =VLOOKUP(D60,'Obs Conc %CV_2'!$C$23:$Q$78,12,FALSE) -> 0 | AB60: =VLOOKUP(D60,'Obs Conc_2'!$C$23:$Q$78,13,FALSE) -> OOR < | AC60: =VLOOKUP(D60,'Obs Conc %CV_2'!$C$23:$Q$78,13,FALSE) -> 0 | AD60: =VLOOKUP(D60,'Obs Conc_2'!$C$23:$Q$78,14,FALSE) -> OOR < | AE60: =VLOOKUP(D60,'Obs Conc %CV_2'!$C$23:$Q$78,14,FALSE) -> 0 | AF60: =VLOOKUP(D60,'Obs Conc_2'!$C$23:$Q$78,15,FALSE) -> OOR < | AG60: =VLOOKUP(D60,'Obs Conc %CV_2'!$C$23:$Q$78,15,FALSE) -> 0
A61: ADRECMO | B61: box 1 | C61: ADRECMO-27_SR_J0 | D61: A060 | E61: serum | F61: =VLOOKUP(D61,'Obs Conc_2'!$C$23:$Q$78,2,FALSE) -> OOR < | G61: =VLOOKUP(D61,'Obs Conc %CV_2'!$C$23:$Q$78,2,FALSE) -> 0 | H61: =VLOOKUP(F61,'Obs Conc_2'!$E$23:$S$78,3,FALSE) -> OOR < | I61: =VLOOKUP(D61,'Obs Conc %CV_2'!$C$23:$Q$78,3,FALSE) -> 0 | J61: =VLOOKUP(D61,'Obs Conc_2'!$C$23:$Q$78,4,FALSE) -> OOR < | K61: =VLOOKUP(D61,'Obs Conc %CV_2'!$C$23:$Q$78,4,FALSE) -> 0 | L61: =VLOOKUP(D61,'Obs Conc_2'!$C$23:$Q$78,5,FALSE) -> OOR < | M61: =VLOOKUP(D61,'Obs Conc %CV_2'!$C$23:$Q$78,5,FALSE) -> 0 | N61: =VLOOKUP(D61,'Obs Conc_2'!$C$23:$Q$78,6,FALSE) -> OOR < | O61: =VLOOKUP(D61,'Obs Conc %CV_2'!$C$23:$Q$78,6,FALSE) -> 0 | P61: =VLOOKUP(D61,'Obs Conc_2'!$C$23:$Q$78,7,FALSE) -> 173.35 | Q61: =VLOOKUP(D61,'Obs Conc %CV_2'!$C$23:$Q$78,7,FALSE) -> 1.9 | R61: =VLOOKUP(D61,'Obs Conc_2'!$C$23:$Q$78,8,FALSE) -> 50.67 | S61: =VLOOKUP(D61,'Obs Conc %CV_2'!$C$23:$Q$78,8,FALSE) -> 0.46 | T61: =VLOOKUP(D61,'Obs Conc_2'!$C$23:$Q$78,9,FALSE) -> 2.25 | U61: =VLOOKUP(D61,'Obs Conc %CV_2'!$C$23:$Q$78,9,FALSE) -> 45.16 | V61: =VLOOKUP(D61,'Obs Conc_2'!$C$23:$Q$78,10,FALSE) -> 699.72 | W61: =VLOOKUP(D61,'Obs Conc %CV_2'!$C$23:$Q$78,10,FALSE) -> 10.81 | X61: =VLOOKUP(D61,'Obs Conc_2'!$C$23:$Q$78,11,FALSE) -> OOR < | Y61: =VLOOKUP(D61,'Obs Conc %CV_2'!$C$23:$Q$78,11,FALSE) -> 0 | Z61: =VLOOKUP(D61,'Obs Conc_2'!$C$23:$Q$78,12,FALSE) -> OOR < | AA61: =VLOOKUP(D61,'Obs Conc %CV_2'!$C$23:$Q$78,12,FALSE) -> 0 | AB61: =VLOOKUP(D61,'Obs Conc_2'!$C$23:$Q$78,13,FALSE) -> OOR < | AC61: =VLOOKUP(D61,'Obs Conc %CV_2'!$C$23:$Q$78,13,FALSE) -> 0 | AD61: =VLOOKUP(D61,'Obs Conc_2'!$C$23:$Q$78,14,FALSE) -> OOR < | AE61: =VLOOKUP(D61,'Obs Conc %CV_2'!$C$23:$Q$78,14,FALSE) -> 0 | AF61: =VLOOKUP(D61,'Obs Conc_2'!$C$23:$Q$78,15,FALSE) -> OOR < | AG61: =VLOOKUP(D61,'Obs Conc %CV_2'!$C$23:$Q$78,15,FALSE) -> 0
A62: ADRECMO | B62: box 1 | C62: ADRECMO-27_SR_J5 | D62: A061 | E62: serum | F62: =VLOOKUP(D62,'Obs Conc_2'!$C$23:$Q$78,2,FALSE) -> OOR < | G62: =VLOOKUP(D62,'Obs Conc %CV_2'!$C$23:$Q$78,2,FALSE) -> 0 | H62: =VLOOKUP(F62,'Obs Conc_2'!$E$23:$S$78,3,FALSE) -> OOR < | I62: =VLOOKUP(D62,'Obs Conc %CV_2'!$C$23:$Q$78,3,FALSE) -> 0 | J62: =VLOOKUP(D62,'Obs Conc_2'!$C$23:$Q$78,4,FALSE) -> OOR < | K62: =VLOOKUP(D62,'Obs Conc %CV_2'!$C$23:$Q$78,4,FALSE) -> 0 | L62: =VLOOKUP(D62,'Obs Conc_2'!$C$23:$Q$78,5,FALSE) -> OOR < | M62: =VLOOKUP(D62,'Obs Conc %CV_2'!$C$23:$Q$78,5,FALSE) -> 0 | N62: =VLOOKUP(D62,'Obs Conc_2'!$C$23:$Q$78,6,FALSE) -> OOR < | O62: =VLOOKUP(D62,'Obs Conc %CV_2'!$C$23:$Q$78,6,FALSE) -> 0 | P62: =VLOOKUP(D62,'Obs Conc_2'!$C$23:$Q$78,7,FALSE) -> 12.76 | Q62: =VLOOKUP(D62,'Obs Conc %CV_2'!$C$23:$Q$78,7,FALSE) -> 28.47 | R62: =VLOOKUP(D62,'Obs Conc_2'!$C$23:$Q$78,8,FALSE) -> *1.37 | S62: =VLOOKUP(D62,'Obs Conc %CV_2'!$C$23:$Q$78,8,FALSE) -> 121.82 | T62: =VLOOKUP(D62,'Obs Conc_2'!$C$23:$Q$78,9,FALSE) -> OOR < | U62: =VLOOKUP(D62,'Obs Conc %CV_2'!$C$23:$Q$78,9,FALSE) -> 0 | V62: =VLOOKUP(D62,'Obs Conc_2'!$C$23:$Q$78,10,FALSE) -> 456.5 | W62: =VLOOKUP(D62,'Obs Conc %CV_2'!$C$23:$Q$78,10,FALSE) -> 4.64 | X62: =VLOOKUP(D62,'Obs Conc_2'!$C$23:$Q$78,11,FALSE) -> OOR < | Y62: =VLOOKUP(D62,'Obs Conc %CV_2'!$C$23:$Q$78,11,FALSE) -> 0 | Z62: =VLOOKUP(D62,'Obs Conc_2'!$C$23:$Q$78,12,FALSE) -> OOR < | AA62: =VLOOKUP(D62,'Obs Conc %CV_2'!$C$23:$Q$78,12,FALSE) -> 0 | AB62: =VLOOKUP(D62,'Obs Conc_2'!$C$23:$Q$78,13,FALSE) -> OOR < | AC62: =VLOOKUP(D62,'Obs Conc %CV_2'!$C$23:$Q$78,13,FALSE) -> 0 | AD62: =VLOOKUP(D62,'Obs Conc_2'!$C$23:$Q$78,14,FALSE) -> OOR < | AE62: =VLOOKUP(D62,'Obs Conc %CV_2'!$C$23:$Q$78,14,FALSE) -> 0 | AF62: =VLOOKUP(D62,'Obs Conc_2'!$C$23:$Q$78,15,FALSE) -> OOR < | AG62: =VLOOKUP(D62,'Obs Conc %CV_2'!$C$23:$Q$78,15,FALSE) -> 0
A63: ADRECMO | B63: box 1 | C63: ADRECMO-28_SR_J0 | D63: A062 | E63: serum | F63: =VLOOKUP(D63,'Obs Conc_2'!$C$23:$Q$78,2,FALSE) -> OOR < | G63: =VLOOKUP(D63,'Obs Conc %CV_2'!$C$23:$Q$78,2,FALSE) -> 0 | H63: =VLOOKUP(F63,'Obs Conc_2'!$E$23:$S$78,3,FALSE) -> OOR < | I63: =VLOOKUP(D63,'Obs Conc %CV_2'!$C$23:$Q$78,3,FALSE) -> 0 | J63: =VLOOKUP(D63,'Obs Conc_2'!$C$23:$Q$78,4,FALSE) -> OOR < | K63: =VLOOKUP(D63,'Obs Conc %CV_2'!$C$23:$Q$78,4,FALSE) -> 0 | L63: =VLOOKUP(D63,'Obs Conc_2'!$C$23:$Q$78,5,FALSE) -> OOR < | M63: =VLOOKUP(D63,'Obs Conc %CV_2'!$C$23:$Q$78,5,FALSE) -> 0 | N63: =VLOOKUP(D63,'Obs Conc_2'!$C$23:$Q$78,6,FALSE) -> OOR < | O63: =VLOOKUP(D63,'Obs Conc %CV_2'!$C$23:$Q$78,6,FALSE) -> 0 | P63: =VLOOKUP(D63,'Obs Conc_2'!$C$23:$Q$78,7,FALSE) -> 448.86 | Q63: =VLOOKUP(D63,'Obs Conc %CV_2'!$C$23:$Q$78,7,FALSE) -> 9.25 | R63: =VLOOKUP(D63,'Obs Conc_2'!$C$23:$Q$78,8,FALSE) -> 26.75 | S63: =VLOOKUP(D63,'Obs Conc %CV_2'!$C$23:$Q$78,8,FALSE) -> 19.43 | T63: =VLOOKUP(D63,'Obs Conc_2'!$C$23:$Q$78,9,FALSE) -> 19.41 | U63: =VLOOKUP(D63,'Obs Conc %CV_2'!$C$23:$Q$78,9,FALSE) -> 11.62 | V63: =VLOOKUP(D63,'Obs Conc_2'!$C$23:$Q$78,10,FALSE) -> 682.55 | W63: =VLOOKUP(D63,'Obs Conc %CV_2'!$C$23:$Q$78,10,FALSE) -> 11.06 | X63: =VLOOKUP(D63,'Obs Conc_2'!$C$23:$Q$78,11,FALSE) -> OOR < | Y63: =VLOOKUP(D63,'Obs Conc %CV_2'!$C$23:$Q$78,11,FALSE) -> 0 | Z63: =VLOOKUP(D63,'Obs Conc_2'!$C$23:$Q$78,12,FALSE) -> OOR < | AA63: =VLOOKUP(D63,'Obs Conc %CV_2'!$C$23:$Q$78,12,FALSE) -> 0 | AB63: =VLOOKUP(D63,'Obs Conc_2'!$C$23:$Q$78,13,FALSE) -> OOR < | AC63: =VLOOKUP(D63,'Obs Conc %CV_2'!$C$23:$Q$78,13,FALSE) -> 0 | AD63: =VLOOKUP(D63,'Obs Conc_2'!$C$23:$Q$78,14,FALSE) -> OOR < | AE63: =VLOOKUP(D63,'Obs Conc %CV_2'!$C$23:$Q$78,14,FALSE) -> 0 | AF63: =VLOOKUP(D63,'Obs Conc_2'!$C$23:$Q$78,15,FALSE) -> OOR < | AG63: =VLOOKUP(D63,'Obs Conc %CV_2'!$C$23:$Q$78,15,FALSE) -> 0
A64: ADRECMO | B64: box 1 | C64: ADRECMO-29_SR_J0 | D64: A063 | E64: serum | F64: =VLOOKUP(D64,'Obs Conc_2'!$C$23:$Q$78,2,FALSE) -> OOR < | G64: =VLOOKUP(D64,'Obs Conc %CV_2'!$C$23:$Q$78,2,FALSE) -> 0 | H64: =VLOOKUP(F64,'Obs Conc_2'!$E$23:$S$78,3,FALSE) -> OOR < | I64: =VLOOKUP(D64,'Obs Conc %CV_2'!$C$23:$Q$78,3,FALSE) -> 0 | J64: =VLOOKUP(D64,'Obs Conc_2'!$C$23:$Q$78,4,FALSE) -> OOR < | K64: =VLOOKUP(D64,'Obs Conc %CV_2'!$C$23:$Q$78,4,FALSE) -> 0 | L64: =VLOOKUP(D64,'Obs Conc_2'!$C$23:$Q$78,5,FALSE) -> OOR < | M64: =VLOOKUP(D64,'Obs Conc %CV_2'!$C$23:$Q$78,5,FALSE) -> 0 | N64: =VLOOKUP(D64,'Obs Conc_2'!$C$23:$Q$78,6,FALSE) -> OOR < | O64: =VLOOKUP(D64,'Obs Conc %CV_2'!$C$23:$Q$78,6,FALSE) -> 0 | P64: =VLOOKUP(D64,'Obs Conc_2'!$C$23:$Q$78,7,FALSE) -> 268.46 | Q64: =VLOOKUP(D64,'Obs Conc %CV_2'!$C$23:$Q$78,7,FALSE) -> 13.77 | R64: =VLOOKUP(D64,'Obs Conc_2'!$C$23:$Q$78,8,FALSE) -> 12.5 | S64: =VLOOKUP(D64,'Obs Conc %CV_2'!$C$23:$Q$78,8,FALSE) -> 18.32 | T64: =VLOOKUP(D64,'Obs Conc_2'!$C$23:$Q$78,9,FALSE) -> 14.51 | U64: =VLOOKUP(D64,'Obs Conc %CV_2'!$C$23:$Q$78,9,FALSE) -> 11.45 | V64: =VLOOKUP(D64,'Obs Conc_2'!$C$23:$Q$78,10,FALSE) -> 481.29 | W64: =VLOOKUP(D64,'Obs Conc %CV_2'!$C$23:$Q$78,10,FALSE) -> 12.51 | X64: =VLOOKUP(D64,'Obs Conc_2'!$C$23:$Q$78,11,FALSE) -> OOR < | Y64: =VLOOKUP(D64,'Obs Conc %CV_2'!$C$23:$Q$78,11,FALSE) -> 0 | Z64: =VLOOKUP(D64,'Obs Conc_2'!$C$23:$Q$78,12,FALSE) -> OOR < | AA64: =VLOOKUP(D64,'Obs Conc %CV_2'!$C$23:$Q$78,12,FALSE) -> 0 | AB64: =VLOOKUP(D64,'Obs Conc_2'!$C$23:$Q$78,13,FALSE) -> OOR < | AC64: =VLOOKUP(D64,'Obs Conc %CV_2'!$C$23:$Q$78,13,FALSE) -> 0 | AD64: =VLOOKUP(D64,'Obs Conc_2'!$C$23:$Q$78,14,FALSE) -> OOR < | AE64: =VLOOKUP(D64,'Obs Conc %CV_2'!$C$23:$Q$78,14,FALSE) -> 0 | AF64: =VLOOKUP(D64,'Obs Conc_2'!$C$23:$Q$78,15,FALSE) -> OOR < | AG64: =VLOOKUP(D64,'Obs Conc %CV_2'!$C$23:$Q$78,15,FALSE) -> 0
A65: ADRECMO | B65: box 1 | C65: ADRECMO-28_SR_J3 | D65: A064 | E65: serum | F65: =VLOOKUP(D65,'Obs Conc_2'!$C$23:$Q$78,2,FALSE) -> OOR < | G65: =VLOOKUP(D65,'Obs Conc %CV_2'!$C$23:$Q$78,2,FALSE) -> 0 | H65: =VLOOKUP(F65,'Obs Conc_2'!$E$23:$S$78,3,FALSE) -> OOR < | I65: =VLOOKUP(D65,'Obs Conc %CV_2'!$C$23:$Q$78,3,FALSE) -> 0 | J65: =VLOOKUP(D65,'Obs Conc_2'!$C$23:$Q$78,4,FALSE) -> OOR < | K65: =VLOOKUP(D65,'Obs Conc %CV_2'!$C$23:$Q$78,4,FALSE) -> 0 | L65: =VLOOKUP(D65,'Obs Conc_2'!$C$23:$Q$78,5,FALSE) -> OOR < | M65: =VLOOKUP(D65,'Obs Conc %CV_2'!$C$23:$Q$78,5,FALSE) -> 0 | N65: =VLOOKUP(D65,'Obs Conc_2'!$C$23:$Q$78,6,FALSE) -> OOR < | O65: =VLOOKUP(D65,'Obs Conc %CV_2'!$C$23:$Q$78,6,FALSE) -> 0 | P65: =VLOOKUP(D65,'Obs Conc_2'!$C$23:$Q$78,7,FALSE) -> 89.57 | Q65: =VLOOKUP(D65,'Obs Conc %CV_2'!$C$23:$Q$78,7,FALSE) -> 22.29 | R65: =VLOOKUP(D65,'Obs Conc_2'!$C$23:$Q$78,8,FALSE) -> 17.82 | S65: =VLOOKUP(D65,'Obs Conc %CV_2'!$C$23:$Q$78,8,FALSE) -> 5.54 | T65: =VLOOKUP(D65,'Obs Conc_2'!$C$23:$Q$78,9,FALSE) -> OOR < | U65: =VLOOKUP(D65,'Obs Conc %CV_2'!$C$23:$Q$78,9,FALSE) -> 0 | V65: =VLOOKUP(D65,'Obs Conc_2'!$C$23:$Q$78,10,FALSE) -> 572.75 | W65: =VLOOKUP(D65,'Obs Conc %CV_2'!$C$23:$Q$78,10,FALSE) -> 3.72 | X65: =VLOOKUP(D65,'Obs Conc_2'!$C$23:$Q$78,11,FALSE) -> OOR < | Y65: =VLOOKUP(D65,'Obs Conc %CV_2'!$C$23:$Q$78,11,FALSE) -> 0 | Z65: =VLOOKUP(D65,'Obs Conc_2'!$C$23:$Q$78,12,FALSE) -> OOR < | AA65: =VLOOKUP(D65,'Obs Conc %CV_2'!$C$23:$Q$78,12,FALSE) -> 0 | AB65: =VLOOKUP(D65,'Obs Conc_2'!$C$23:$Q$78,13,FALSE) -> OOR < | AC65: =VLOOKUP(D65,'Obs Conc %CV_2'!$C$23:$Q$78,13,FALSE) -> 0 | AD65: =VLOOKUP(D65,'Obs Conc_2'!$C$23:$Q$78,14,FALSE) -> OOR < | AE65: =VLOOKUP(D65,'Obs Conc %CV_2'!$C$23:$Q$78,14,FALSE) -> 0 | AF65: =VLOOKUP(D65,'Obs Conc_2'!$C$23:$Q$78,15,FALSE) -> OOR < | AG65: =VLOOKUP(D65,'Obs Conc %CV_2'!$C$23:$Q$78,15,FALSE) -> 0
A66: ADRECMO | B66: box 1 | C66: ADRECMO-29_SR_J5 | D66: A065 | E66: serum | F66: =VLOOKUP(D66,'Obs Conc_2'!$C$23:$Q$78,2,FALSE) -> OOR < | G66: =VLOOKUP(D66,'Obs Conc %CV_2'!$C$23:$Q$78,2,FALSE) -> 0 | H66: =VLOOKUP(F66,'Obs Conc_2'!$E$23:$S$78,3,FALSE) -> OOR < | I66: =VLOOKUP(D66,'Obs Conc %CV_2'!$C$23:$Q$78,3,FALSE) -> 0 | J66: =VLOOKUP(D66,'Obs Conc_2'!$C$23:$Q$78,4,FALSE) -> OOR < | K66: =VLOOKUP(D66,'Obs Conc %CV_2'!$C$23:$Q$78,4,FALSE) -> 0 | L66: =VLOOKUP(D66,'Obs Conc_2'!$C$23:$Q$78,5,FALSE) -> OOR < | M66: =VLOOKUP(D66,'Obs Conc %CV_2'!$C$23:$Q$78,5,FALSE) -> 0 | N66: =VLOOKUP(D66,'Obs Conc_2'!$C$23:$Q$78,6,FALSE) -> OOR < | O66: =VLOOKUP(D66,'Obs Conc %CV_2'!$C$23:$Q$78,6,FALSE) -> 0 | P66: =VLOOKUP(D66,'Obs Conc_2'!$C$23:$Q$78,7,FALSE) -> 18.55 | Q66: =VLOOKUP(D66,'Obs Conc %CV_2'!$C$23:$Q$78,7,FALSE) -> 0 | R66: =VLOOKUP(D66,'Obs Conc_2'!$C$23:$Q$78,8,FALSE) -> 9.91 | S66: =VLOOKUP(D66,'Obs Conc %CV_2'!$C$23:$Q$78,8,FALSE) -> 0 | T66: =VLOOKUP(D66,'Obs Conc_2'!$C$23:$Q$78,9,FALSE) -> OOR < | U66: =VLOOKUP(D66,'Obs Conc %CV_2'!$C$23:$Q$78,9,FALSE) -> 0 | V66: =VLOOKUP(D66,'Obs Conc_2'!$C$23:$Q$78,10,FALSE) -> 310.22 | W66: =VLOOKUP(D66,'Obs Conc %CV_2'!$C$23:$Q$78,10,FALSE) -> 0 | X66: =VLOOKUP(D66,'Obs Conc_2'!$C$23:$Q$78,11,FALSE) -> OOR < | Y66: =VLOOKUP(D66,'Obs Conc %CV_2'!$C$23:$Q$78,11,FALSE) -> 0 | Z66: =VLOOKUP(D66,'Obs Conc_2'!$C$23:$Q$78,12,FALSE) -> OOR < | AA66: =VLOOKUP(D66,'Obs Conc %CV_2'!$C$23:$Q$78,12,FALSE) -> 0 | AB66: =VLOOKUP(D66,'Obs Conc_2'!$C$23:$Q$78,13,FALSE) -> OOR < | AC66: =VLOOKUP(D66,'Obs Conc %CV_2'!$C$23:$Q$78,13,FALSE) -> 0 | AD66: =VLOOKUP(D66,'Obs Conc_2'!$C$23:$Q$78,14,FALSE) -> OOR < | AE66: =VLOOKUP(D66,'Obs Conc %CV_2'!$C$23:$Q$78,14,FALSE) -> 0 | AF66: =VLOOKUP(D66,'Obs Conc_2'!$C$23:$Q$78,15,FALSE) -> OOR < | AG66: =VLOOKUP(D66,'Obs Conc %CV_2'!$C$23:$Q$78,15,FALSE) -> 0
A67: ADRECMO | B67: box 1 | C67: ADRECMO-29_SR_JS | D67: A066 | E67: serum | F67: =VLOOKUP(D67,'Obs Conc_2'!$C$23:$Q$78,2,FALSE) -> OOR < | G67: =VLOOKUP(D67,'Obs Conc %CV_2'!$C$23:$Q$78,2,FALSE) -> 0 | H67: =VLOOKUP(F67,'Obs Conc_2'!$E$23:$S$78,3,FALSE) -> OOR < | I67: =VLOOKUP(D67,'Obs Conc %CV_2'!$C$23:$Q$78,3,FALSE) -> 0 | J67: =VLOOKUP(D67,'Obs Conc_2'!$C$23:$Q$78,4,FALSE) -> OOR < | K67: =VLOOKUP(D67,'Obs Conc %CV_2'!$C$23:$Q$78,4,FALSE) -> 0 | L67: =VLOOKUP(D67,'Obs Conc_2'!$C$23:$Q$78,5,FALSE) -> OOR < | M67: =VLOOKUP(D67,'Obs Conc %CV_2'!$C$23:$Q$78,5,FALSE) -> 0 | N67: =VLOOKUP(D67,'Obs Conc_2'!$C$23:$Q$78,6,FALSE) -> OOR < | O67: =VLOOKUP(D67,'Obs Conc %CV_2'!$C$23:$Q$78,6,FALSE) -> 0 | P67: =VLOOKUP(D67,'Obs Conc_2'!$C$23:$Q$78,7,FALSE) -> 94.03 | Q67: =VLOOKUP(D67,'Obs Conc %CV_2'!$C$23:$Q$78,7,FALSE) -> 0 | R67: =VLOOKUP(D67,'Obs Conc_2'!$C$23:$Q$78,8,FALSE) -> 6.49 | S67: =VLOOKUP(D67,'Obs Conc %CV_2'!$C$23:$Q$78,8,FALSE) -> 0 | T67: =VLOOKUP(D67,'Obs Conc_2'!$C$23:$Q$78,9,FALSE) -> OOR < | U67: =VLOOKUP(D67,'Obs Conc %CV_2'!$C$23:$Q$78,9,FALSE) -> 0 | V67: =VLOOKUP(D67,'Obs Conc_2'!$C$23:$Q$78,10,FALSE) -> 497.67 | W67: =VLOOKUP(D67,'Obs Conc %CV_2'!$C$23:$Q$78,10,FALSE) -> 0 | X67: =VLOOKUP(D67,'Obs Conc_2'!$C$23:$Q$78,11,FALSE) -> OOR < | Y67: =VLOOKUP(D67,'Obs Conc %CV_2'!$C$23:$Q$78,11,FALSE) -> 0 | Z67: =VLOOKUP(D67,'Obs Conc_2'!$C$23:$Q$78,12,FALSE) -> OOR < | AA67: =VLOOKUP(D67,'Obs Conc %CV_2'!$C$23:$Q$78,12,FALSE) -> 0 | AB67: =VLOOKUP(D67,'Obs Conc_2'!$C$23:$Q$78,13,FALSE) -> OOR < | AC67: =VLOOKUP(D67,'Obs Conc %CV_2'!$C$23:$Q$78,13,FALSE) -> 0 | AD67: =VLOOKUP(D67,'Obs Conc_2'!$C$23:$Q$78,14,FALSE) -> OOR < | AE67: =VLOOKUP(D67,'Obs Conc %CV_2'!$C$23:$Q$78,14,FALSE) -> 0 | AF67: =VLOOKUP(D67,'Obs Conc_2'!$C$23:$Q$78,15,FALSE) -> OOR < | AG67: =VLOOKUP(D67,'Obs Conc %CV_2'!$C$23:$Q$78,15,FALSE) -> 0
A68: ADRECMO | B68: box 1 | C68: ADRECMO-30_SR_J0 | D68: A067 | E68: serum | F68: =VLOOKUP(D68,'Obs Conc_2'!$C$23:$Q$78,2,FALSE) -> OOR < | G68: =VLOOKUP(D68,'Obs Conc %CV_2'!$C$23:$Q$78,2,FALSE) -> 0 | H68: =VLOOKUP(F68,'Obs Conc_2'!$E$23:$S$78,3,FALSE) -> OOR < | I68: =VLOOKUP(D68,'Obs Conc %CV_2'!$C$23:$Q$78,3,FALSE) -> 0 | J68: =VLOOKUP(D68,'Obs Conc_2'!$C$23:$Q$78,4,FALSE) -> OOR < | K68: =VLOOKUP(D68,'Obs Conc %CV_2'!$C$23:$Q$78,4,FALSE) -> 0 | L68: =VLOOKUP(D68,'Obs Conc_2'!$C$23:$Q$78,5,FALSE) -> OOR < | M68: =VLOOKUP(D68,'Obs Conc %CV_2'!$C$23:$Q$78,5,FALSE) -> 0 | N68: =VLOOKUP(D68,'Obs Conc_2'!$C$23:$Q$78,6,FALSE) -> 6.32 | O68: =VLOOKUP(D68,'Obs Conc %CV_2'!$C$23:$Q$78,6,FALSE) -> 0 | P68: =VLOOKUP(D68,'Obs Conc_2'!$C$23:$Q$78,7,FALSE) -> 13.61 | Q68: =VLOOKUP(D68,'Obs Conc %CV_2'!$C$23:$Q$78,7,FALSE) -> 0 | R68: =VLOOKUP(D68,'Obs Conc_2'!$C$23:$Q$78,8,FALSE) -> 14.37 | S68: =VLOOKUP(D68,'Obs Conc %CV_2'!$C$23:$Q$78,8,FALSE) -> 0 | T68: =VLOOKUP(D68,'Obs Conc_2'!$C$23:$Q$78,9,FALSE) -> OOR < | U68: =VLOOKUP(D68,'Obs Conc %CV_2'!$C$23:$Q$78,9,FALSE) -> 0 | V68: =VLOOKUP(D68,'Obs Conc_2'!$C$23:$Q$78,10,FALSE) -> 701.63 | W68: =VLOOKUP(D68,'Obs Conc %CV_2'!$C$23:$Q$78,10,FALSE) -> 0 | X68: =VLOOKUP(D68,'Obs Conc_2'!$C$23:$Q$78,11,FALSE) -> OOR < | Y68: =VLOOKUP(D68,'Obs Conc %CV_2'!$C$23:$Q$78,11,FALSE) -> 0 | Z68: =VLOOKUP(D68,'Obs Conc_2'!$C$23:$Q$78,12,FALSE) -> OOR < | AA68: =VLOOKUP(D68,'Obs Conc %CV_2'!$C$23:$Q$78,12,FALSE) -> 0 | AB68: =VLOOKUP(D68,'Obs Conc_2'!$C$23:$Q$78,13,FALSE) -> OOR < | AC68: =VLOOKUP(D68,'Obs Conc %CV_2'!$C$23:$Q$78,13,FALSE) -> 0 | AD68: =VLOOKUP(D68,'Obs Conc_2'!$C$23:$Q$78,14,FALSE) -> OOR < | AE68: =VLOOKUP(D68,'Obs Conc %CV_2'!$C$23:$Q$78,14,FALSE) -> 0 | AF68: =VLOOKUP(D68,'Obs Conc_2'!$C$23:$Q$78,15,FALSE) -> OOR < | AG68: =VLOOKUP(D68,'Obs Conc %CV_2'!$C$23:$Q$78,15,FALSE) -> 0
A69: ADRECMO | B69: box 1 | C69: ADRECMO-30_SR_J3-J5 | D69: A068 | E69: serum | F69: =VLOOKUP(D69,'Obs Conc_2'!$C$23:$Q$78,2,FALSE) -> OOR < | G69: =VLOOKUP(D69,'Obs Conc %CV_2'!$C$23:$Q$78,2,FALSE) -> 0 | H69: =VLOOKUP(F69,'Obs Conc_2'!$E$23:$S$78,3,FALSE) -> OOR < | I69: =VLOOKUP(D69,'Obs Conc %CV_2'!$C$23:$Q$78,3,FALSE) -> 0 | J69: =VLOOKUP(D69,'Obs Conc_2'!$C$23:$Q$78,4,FALSE) -> OOR < | K69: =VLOOKUP(D69,'Obs Conc %CV_2'!$C$23:$Q$78,4,FALSE) -> 0 | L69: =VLOOKUP(D69,'Obs Conc_2'!$C$23:$Q$78,5,FALSE) -> OOR < | M69: =VLOOKUP(D69,'Obs Conc %CV_2'!$C$23:$Q$78,5,FALSE) -> 0 | N69: =VLOOKUP(D69,'Obs Conc_2'!$C$23:$Q$78,6,FALSE) -> OOR < | O69: =VLOOKUP(D69,'Obs Conc %CV_2'!$C$23:$Q$78,6,FALSE) -> 0 | P69: =VLOOKUP(D69,'Obs Conc_2'!$C$23:$Q$78,7,FALSE) -> 24.86 | Q69: =VLOOKUP(D69,'Obs Conc %CV_2'!$C$23:$Q$78,7,FALSE) -> 0 | R69: =VLOOKUP(D69,'Obs Conc_2'!$C$23:$Q$78,8,FALSE) -> 8.54 | S69: =VLOOKUP(D69,'Obs Conc %CV_2'!$C$23:$Q$78,8,FALSE) -> 0 | T69: =VLOOKUP(D69,'Obs Conc_2'!$C$23:$Q$78,9,FALSE) -> OOR < | U69: =VLOOKUP(D69,'Obs Conc %CV_2'!$C$23:$Q$78,9,FALSE) -> 0 | V69: =VLOOKUP(D69,'Obs Conc_2'!$C$23:$Q$78,10,FALSE) -> 715.03 | W69: =VLOOKUP(D69,'Obs Conc %CV_2'!$C$23:$Q$78,10,FALSE) -> 0 | X69: =VLOOKUP(D69,'Obs Conc_2'!$C$23:$Q$78,11,FALSE) -> OOR < | Y69: =VLOOKUP(D69,'Obs Conc %CV_2'!$C$23:$Q$78,11,FALSE) -> 0 | Z69: =VLOOKUP(D69,'Obs Conc_2'!$C$23:$Q$78,12,FALSE) -> OOR < | AA69: =VLOOKUP(D69,'Obs Conc %CV_2'!$C$23:$Q$78,12,FALSE) -> 0 | AB69: =VLOOKUP(D69,'Obs Conc_2'!$C$23:$Q$78,13,FALSE) -> OOR < | AC69: =VLOOKUP(D69,'Obs Conc %CV_2'!$C$23:$Q$78,13,FALSE) -> 0 | AD69: =VLOOKUP(D69,'Obs Conc_2'!$C$23:$Q$78,14,FALSE) -> OOR < | AE69: =VLOOKUP(D69,'Obs Conc %CV_2'!$C$23:$Q$78,14,FALSE) -> 0 | AF69: =VLOOKUP(D69,'Obs Conc_2'!$C$23:$Q$78,15,FALSE) -> OOR < | AG69: =VLOOKUP(D69,'Obs Conc %CV_2'!$C$23:$Q$78,15,FALSE) -> 0
... A113: ADRECMO | B113: box 2 | C113: ADRECMO-50_SR_JS | D113: A112 | E113: serum | F113: =VLOOKUP(D113,'Obs Conc_2'!$C$23:$Q$78,2,FALSE) -> OOR < | G113: =VLOOKUP(D113,'Obs Conc %CV_2'!$C$23:$Q$78,2,FALSE) -> 0 | H113: =VLOOKUP(F113,'Obs Conc_2'!$E$23:$S$78,3,FALSE) -> OOR < | I113: =VLOOKUP(D113,'Obs Conc %CV_2'!$C$23:$Q$78,3,FALSE) -> 0 | J113: =VLOOKUP(D113,'Obs Conc_2'!$C$23:$Q$78,4,FALSE) -> OOR < | K113: =VLOOKUP(D113,'Obs Conc %CV_2'!$C$23:$Q$78,4,FALSE) -> 0 | L113: =VLOOKUP(D113,'Obs Conc_2'!$C$23:$Q$78,5,FALSE) -> OOR < | M113: =VLOOKUP(D113,'Obs Conc %CV_2'!$C$23:$Q$78,5,FALSE) -> 0 | N113: =VLOOKUP(D113,'Obs Conc_2'!$C$23:$Q$78,6,FALSE) -> OOR < | O113: =VLOOKUP(D113,'Obs Conc %CV_2'!$C$23:$Q$78,6,FALSE) -> 0 | P113: =VLOOKUP(D113,'Obs Conc_2'!$C$23:$Q$78,7,FALSE) -> 26.4 | Q113: =VLOOKUP(D113,'Obs Conc %CV_2'!$C$23:$Q$78,7,FALSE) -> 49.88 | R113: =VLOOKUP(D113,'Obs Conc_2'!$C$23:$Q$78,8,FALSE) -> *1.37 | S113: =VLOOKUP(D113,'Obs Conc %CV_2'!$C$23:$Q$78,8,FALSE) -> 0 | T113: =VLOOKUP(D113,'Obs Conc_2'!$C$23:$Q$78,9,FALSE) -> OOR < | U113: =VLOOKUP(D113,'Obs Conc %CV_2'!$C$23:$Q$78,9,FALSE) -> 0 | V113: =VLOOKUP(D113,'Obs Conc_2'!$C$23:$Q$78,10,FALSE) -> 237.93 | W113: =VLOOKUP(D113,'Obs Conc %CV_2'!$C$23:$Q$78,10,FALSE) -> 25.17 | X113: =VLOOKUP(D113,'Obs Conc_2'!$C$23:$Q$78,11,FALSE) -> OOR < | Y113: =VLOOKUP(D113,'Obs Conc %CV_2'!$C$23:$Q$78,11,FALSE) -> 0 | Z113: =VLOOKUP(D113,'Obs Conc_2'!$C$23:$Q$78,12,FALSE) -> OOR < | AA113: =VLOOKUP(D113,'Obs Conc %CV_2'!$C$23:$Q$78,12,FALSE) -> 0 | AB113: =VLOOKUP(D113,'Obs Conc_2'!$C$23:$Q$78,13,FALSE) -> OOR < | AC113: =VLOOKUP(D113,'Obs Conc %CV_2'!$C$23:$Q$78,13,FALSE) -> 0 | AD113: =VLOOKUP(D113,'Obs Conc_2'!$C$23:$Q$78,14,FALSE) -> OOR < | AE113: =VLOOKUP(D113,'Obs Conc %CV_2'!$C$23:$Q$78,14,FALSE) -> 0 | AF113: =VLOOKUP(D113,'Obs Conc_2'!$C$23:$Q$78,15,FALSE) -> OOR < | AG113: =VLOOKUP(D113,'Obs Conc %CV_2'!$C$23:$Q$78,15,FALSE) -> 0

Sheet calculs OOR
A1: Study | B1: box n° | C1: Sample ID number | E1: Type | F1: [IL-33] in pg/mL | G1: IL-33 CV in % | H1: [IL1b] in pg/mL | I1: IL1b CV in % | J1: [IL2] in pg/mL | K1: IL2 CV in % | L1: [IL4] in pg/mL | M1: IL4 CV in % | N1: [IL5] in pg/mL | O1: IL5 CV in % | P1: [IL6] in pg/mL | Q1: IL6 CV in % | R1: [IL8/CXCL8] in pg/mL | S1: IL8/CXCL8 CV in % | T1: [IL10] in pg/mL | U1: IL10 CV in % | V1: [GDF-15] in pg/mL | W1: GDF-15 CV in % | X1: [IL12p70] in pg/mL | Y1: IL12p70 CV in % | Z1: [IL17A/CTLA-8] in pg/mL | AA1: IL17A/CTLA-8 CV in % | AB1: [IFNg] in pg/mL | AC1: IFNg CV in % | AD1: [TNFa] in pg/mL | AE1: TNFa CV in % | AF1: [Granzyme B] in pg/mL | AG1: Granzyme B CV in %
A2: ADRECMO | B2: box 1 | C2: ADRECMO-01_SR_J0 | D2: A001 | E2: serum | F2: OOR < | G2: 0 | H2: OOR < | I2: 0 | J2: OOR < | K2: 0 | L2: OOR < | M2: 0 | N2: OOR < | O2: 0 | P2: 25.35 | Q2: 8.07 | R2: 9.83 | S2: 15.32 | T2: OOR < | U2: 0 | V2: 405.42 | W2: 15.5 | X2: OOR < | Y2: 0 | Z2: OOR < | AA2: 0 | AB2: OOR < | AC2: 0 | AD2: OOR < | AE2: 0 | AF2: OOR < | AG2: 0
A3: ADRECMO | B3: box 1 | C3: ADRECMO-01_SR_J3-J5 | D3: A002 | E3: serum | F3: OOR < | G3: 0 | H3: OOR < | I3: 0 | J3: OOR < | K3: 0 | L3: OOR < | M3: 0 | N3: *2,50 | O3: 73.6 | P3: 47.13 | Q3: 9.01 | R3: 3.29 | S3: 7.48 | T3: OOR < | U3: 0 | V3: 313.34 | W3: 0.64 | X3: OOR < | Y3: 0 | Z3: OOR < | AA3: 0 | AB3: OOR < | AC3: 0 | AD3: OOR < | AE3: 0 | AF3: OOR < | AG3: 0
A4: ADRECMO | B4: box 1 | C4: ADRECMO-01_SR_JS | D4: A003 | E4: serum | F4: OOR < | G4: 0 | H4: OOR < | I4: 0 | J4: OOR < | K4: 0 | L4: OOR < | M4: 0 | N4: *0,01 | O4: 0 | P4: 53.41 | Q4: 26.14 | R4: 3.47 | S4: 31.95 | T4: OOR < | U4: 0 | V4: 379.9 | W4: 19.7 | X4: OOR < | Y4: 0 | Z4: OOR < | AA4: 0 | AB4: OOR < | AC4: 0 | AD4: OOR < | AE4: 0 | AF4: OOR < | AG4: 0
A5: ADRECMO | B5: box 1 | C5: ADRECMO-02_SR_J0 | D5: A004 | E5: serum | F5: OOR < | G5: 0 | H5: OOR < | I5: 0 | J5: OOR < | K5: 0 | L5: OOR < | M5: 0 | N5: *5,19 | O5: 0 | P5: 416.67 | Q5: 5.37 | R5: 87.29 | S5: 1.37 | T5: 105.86 | U5: 4.04 | V5: 660.73 | W5: 4.57 | X5: OOR < | Y5: 0 | Z5: OOR < | AA5: 0 | AB5: OOR < | AC5: 0 | AD5: OOR < | AE5: 0 | AF5: OOR < | AG5: 0
A6: ADRECMO | B6: box 1 | C6: ADRECMO-02_SR_J3-J5 | D6: A005 | E6: serum | F6: OOR < | G6: 0 | H6: OOR < | I6: 0 | J6: OOR < | K6: 0 | L6: OOR < | M6: 0 | N6: *6,56 | O6: 0 | P6: 50.78 | Q6: 1.84 | R6: 18.75 | S6: 12.99 | T6: *1,52 | U6: 11.84 | V6: 580.6 | W6: 9.12 | X6: OOR < | Y6: 0 | Z6: OOR < | AA6: 0 | AB6: OOR < | AC6: 0 | AD6: OOR < | AE6: 0 | AF6: OOR < | AG6: 0
A7: ADRECMO | B7: box 1 | C7: ADRECMO-02_SR_JS | D7: A006 | E7: serum | F7: OOR < | G7: 0 | H7: OOR < | I7: 0 | J7: OOR < | K7: 0 | L7: OOR < | M7: 0 | N7: *6,56 | O7: 59.21 | P7: 55.37 | Q7: 13.35 | R7: 22.31 | S7: 24.31 | T7: 4.12 | U7: 25.17 | V7: 655.39 | W7: 6.59 | X7: OOR < | Y7: 0 | Z7: OOR < | AA7: 0 | AB7: OOR < | AC7: 0 | AD7: OOR < | AE7: 0 | AF7: OOR < | AG7: 0
A8: ADRECMO | B8: box 1 | C8: ADRECMO-03_SR_J0 | D8: A007 | E8: serum | F8: OOR < | G8: 0 | H8: OOR < | I8: 0 | J8: OOR < | K8: 0 | L8: OOR < | M8: 0 | N8: *0,01 | O8: 0 | P8: 90.99 | Q8: 6.18 | R8: 2.81 | S8: 19.94 | T8: 10.4 | U8: 17.37 | V8: 423.87 | W8: 7.74 | X8: OOR < | Y8: 0 | Z8: OOR < | AA8: 0 | AB8: OOR < | AC8: 0 | AD8: OOR < | AE8: 0 | AF8: OOR < | AG8: 0
A9: ADRECMO | B9: box 1 | C9: ADRECMO-03_SR_J3 | D9: A008 | E9: serum | F9: OOR < | G9: 0 | H9: OOR < | I9: 0 | J9: OOR < | K9: 0 | L9: OOR < | M9: 0 | N9: *3,83 | O9: 97.42 | P9: 59.92 | Q9: 7.63 | R9: 2.5 | S9: 20.07 | T9: OOR < | U9: 0 | V9: 416.77 | W9: 1.61 | X9: OOR < | Y9: 0 | Z9: OOR < | AA9: 0 | AB9: OOR < | AC9: 0 | AD9: OOR < | AE9: 0 | AF9: OOR < | AG9: 0
A10: ADRECMO | B10: box 1 | C10: ADRECMO-03_SR_JS | D10: A009 | E10: serum | F10: OOR < | G10: 0 | H10: OOR < | I10: 0 | J10: OOR < | K10: 0 | L10: OOR < | M10: 0 | N10: OOR < | O10: 0 | P10: 42.76 | Q10: 0 | R10: 5.77 | S10: 0 | T10: OOR < | U10: 0 | V10: 613.32 | W10: 0 | X10: OOR < | Y10: 0 | Z10: OOR < | AA10: 0 | AB10: OOR < | AC10: 0 | AD10: OOR < | AE10: 0 | AF10: OOR < | AG10: 0
A11: ADRECMO | B11: box 1 | C11: ADRECMO-04_SR_J0 | D11: A010 | E11: serum | F11: OOR < | G11: 0 | H11: OOR < | I11: 0 | J11: OOR < | K11: 0 | L11: OOR < | M11: 0 | N11: 9.36 | O11: 0 | P11: 347.38 | Q11: 0 | R11: 47.59 | S11: 0 | T11: 17.34 | U11: 0 | V11: 308.15 | W11: 0 | X11: OOR < | Y11: 0 | Z11: OOR < | AA11: 0 | AB11: OOR < | AC11: 0 | AD11: OOR < | AE11: 0 | AF11: OOR < | AG11: 0
A12: ADRECMO | B12: box 1 | C12: ADRECMO-04_SR_J3 | D12: A011 | E12: serum | F12: OOR < | G12: 0 | H12: OOR < | I12: 0 | J12: OOR < | K12: 0 | L12: OOR < | M12: 0 | N12: OOR < | O12: 0 | P12: 13.34 | Q12: 0 | R12: *2,06 | S12: 0 | T12: OOR < | U12: 0 | V12: 267.51 | W12: 0 | X12: OOR < | Y12: 0 | Z12: OOR < | AA12: 0 | AB12: OOR < | AC12: 0 | AD12: OOR < | AE12: 0 | AF12: OOR < | AG12: 0
A13: ADRECMO | B13: box 1 | C13: ADRECMO-04_SR_JS | D13: A012 | E13: serum | F13: OOR < | G13: 0 | H13: OOR < | I13: 0 | J13: OOR < | K13: 0 | L13: OOR < | M13: 0 | N13: *1,21 | O13: 0 | P13: 8.49 | Q13: 0 | R13: 8.1 | S13: 0 | T13: OOR < | U13: 0 | V13: 327.98 | W13: 0 | X13: OOR < | Y13: 0 | Z13: OOR < | AA13: 0 | AB13: OOR < | AC13: 0 | AD13: OOR < | AE13: 0 | AF13: OOR < | AG13: 0
A14: ADRECMO | B14: box 1 | C14: ADRECMO-05_SR_J0 | D14: A013 | E14: serum | F14: OOR < | G14: 0 | H14: OOR < | I14: 0 | J14: OOR < | K14: 0 | L14: OOR < | M14: 0 | N14: *1,21 | O14: 0 | P14: 290.74 | Q14: 0 | R14: 114.27 | S14: 0 | T14: 9.42 | U14: 0 | V14: 2386.6 | W14: 0 | X14: OOR < | Y14: 0 | Z14: OOR < | AA14: 0 | AB14: OOR < | AC14: 0 | AD14: OOR < | AE14: 0 | AF14: OOR < | AG14: 0
A15: ADRECMO | B15: box 1 | C15: ADRECMO-05_SR_J3 | D15: A014 | E15: serum | F15: OOR < | G15: 0 | H15: OOR < | I15: 0 | J15: OOR < | K15: 0 | L15: OOR < | M15: 0 | N15: 12.19 | O15: 0 | P15: 142.29 | Q15: 0 | R15: 31.57 | S15: 0 | T15: 5.1 | U15: 0 | V15: 1455.97 | W15: 0 | X15: OOR < | Y15: 0 | Z15: OOR < | AA15: 0 | AB15: OOR < | AC15: 0 | AD15: OOR < | AE15: 0 | AF15: OOR < | AG15: 0
A16: ADRECMO | B16: box 1 | C16: ADRECMO-06_SR_J0 | D16: A015 | E16: serum | F16: OOR < | G16: 0 | H16: OOR < | I16: 0 | J16: OOR < | K16: 0 | L16: OOR < | M16: 0 | N16: *3,83 | O16: 0 | P16: 227.73 | Q16: 0 | R16: 36.68 | S16: 0 | T16: OOR < | U16: 0 | V16: 633.6 | W16: 0 | X16: OOR < | Y16: 0 | Z16: OOR < | AA16: 0 | AB16: OOR < | AC16: 0 | AD16: OOR < | AE16: 0 | AF16: OOR < | AG16: 0
A17: ADRECMO | B17: box 1 | C17: ADRECMO-06_SR_J3 | D17: A016 | E17: serum | F17: OOR < | G17: 0 | H17: OOR < | I17: 0 | J17: OOR < | K17: 0 | L17: OOR < | M17: 0 | N17: *1,21 | O17: 0 | P17: 78.32 | Q17: 0 | R17: 14.38 | S17: 0 | T17: OOR < | U17: 0 | V17: 506.95 | W17: 0 | X17: OOR < | Y17: 0 | Z17: OOR < | AA17: 0 | AB17: OOR < | AC17: 0 | AD17: OOR < | AE17: 0 | AF17: OOR < | AG17: 0
A18: ADRECMO | B18: box 1 | C18: ADRECMO-06_SR_JS | D18: A017 | E18: serum | F18: OOR < | G18: 0 | H18: OOR < | I18: 0 | J18: OOR < | K18: 0 | L18: OOR < | M18: 0 | N18: OOR < | O18: 0 | P18: 18.72 | Q18: 0 | R18: 5.26 | S18: 0 | T18: OOR < | U18: 0 | V18: 398.8 | W18: 0 | X18: OOR < | Y18: 0 | Z18: OOR < | AA18: 0 | AB18: OOR < | AC18: 0 | AD18: OOR < | AE18: 0 | AF18: OOR < | AG18: 0
A19: ADRECMO | B19: box 1 | C19: ADRECMO-07_SR_J0 | D19: A018 | E19: serum | F19: OOR < | G19: 0 | H19: OOR < | I19: 0 | J19: OOR < | K19: 0 | L19: OOR < | M19: 0 | N19: 15.07 | O19: 0 | P19: 2035.06 | Q19: 0 | R19: 179.94 | S19: 0 | T19: 212.38 | U19: 0 | V19: 711.38 | W19: 0 | X19: OOR < | Y19: 0 | Z19: OOR < | AA19: 0 | AB19: OOR < | AC19: 0 | AD19: 2.18 | AE19: 0 | AF19: OOR < | AG19: 0
A20: ADRECMO | B20: box 1 | C20: ADRECMO-07_SR_J3 | D20: A019 | E20: serum | F20: OOR < | G20: 0 | H20: OOR < | I20: 0 | J20: OOR < | K20: 0 | L20: OOR < | M20: 0 | N20: OOR < | O20: 0 | P20: 72.05 | Q20: 0 | R20: 217.63 | S20: 0 | T20: 3.14 | U20: 0 | V20: 2242.26 | W20: 0 | X20: OOR < | Y20: 0 | Z20: OOR < | AA20: 0 | AB20: OOR < | AC20: 0 | AD20: OOR < | AE20: 0 | AF20: OOR < | AG20: 0
A21: ADRECMO | B21: box 1 | C21: ADRECMO-07_SR_JS | D21: A020 | E21: serum | F21: OOR < | G21: 0 | H21: OOR < | I21: 0 | J21: OOR < | K21: 0 | L21: OOR < | M21: 0 | N21: *1,21 | O21: 0 | P21: 61.21 | Q21: 0 | R21: 193.3 | S21: 0 | T21: 4.61 | U21: 0 | V21: 737.83 | W21: 0 | X21: OOR < | Y21: 0 | Z21: OOR < | AA21: 0 | AB21: OOR < | AC21: 0 | AD21: OOR < | AE21: 0 | AF21: OOR < | AG21: 0
A22: ADRECMO | B22: box 1 | C22: ADRECMO-08_SR_J0 | D22: A021 | E22: serum | F22: OOR < | G22: 0 | H22: OOR < | I22: 0 | J22: OOR < | K22: 0 | L22: OOR < | M22: 0 | N22: OOR < | O22: 0 | P22: 14.9 | Q22: 0 | R22: *0,66 | S22: 0 | T22: OOR < | U22: 0 | V22: 264.67 | W22: 0 | X22: OOR < | Y22: 0 | Z22: OOR < | AA22: 0 | AB22: OOR < | AC22: 0 | AD22: OOR < | AE22: 0 | AF22: OOR < | AG22: 0
A23: ADRECMO | B23: box 1 | C23: ADRECMO-08_SR_J3 | D23: A022 | E23: serum | F23: OOR < | G23: 0 | H23: OOR < | I23: 0 | J23: OOR < | K23: 0 | L23: OOR < | M23: 0 | N23: OOR < | O23: 0 | P23: 17.2 | Q23: 0 | R23: 2.68 | S23: 0 | T23: OOR < | U23: 0 | V23: 289.26 | W23: 0 | X23: OOR < | Y23: 0 | Z23: OOR < | AA23: 0 | AB23: OOR < | AC23: 0 | AD23: OOR < | AE23: 0 | AF23: OOR < | AG23: 0
A24: ADRECMO | B24: box 1 | C24: ADRECMO-08_SR_JS | D24: A023 | E24: serum | F24: OOR < | G24: 0 | H24: OOR < | I24: 0 | J24: OOR < | K24: 0 | L24: OOR < | M24: 0 | N24: OOR < | O24: 0 | P24: OOR < | Q24: 0 | R24: *0,86 | S24: 0 | T24: OOR < | U24: 0 | V24: 330.81 | W24: 0 | X24: OOR < | Y24: 0 | Z24: OOR < | AA24: 0 | AB24: OOR < | AC24: 0 | AD24: OOR < | AE24: 0 | AF24: OOR < | AG24: 0
A25: ADRECMO | B25: box 1 | C25: ADRECMO-09_SR_J0 | D25: A024 | E25: serum | F25: OOR < | G25: 0 | H25: OOR < | I25: 0 | J25: OOR < | K25: 0 | L25: OOR < | M25: 0 | N25: *3,83 | O25: 0 | P25: 46.13 | Q25: 0 | R25: 5.77 | S25: 0 | T25: *0,48 | U25: 0 | V25: 291.15 | W25: 0 | X25: OOR < | Y25: 0 | Z25: OOR < | AA25: 0 | AB25: OOR < | AC25: 0 | AD25: OOR < | AE25: 0 | AF25: OOR < | AG25: 0
A26: ADRECMO | B26: box 1 | C26: ADRECMO-09_SR_J3 | D26: A025 | E26: serum | F26: OOR < | G26: 0 | H26: OOR < | I26: 0 | J26: OOR < | K26: 0 | L26: OOR < | M26: 0 | N26: *1,21 | O26: 0 | P26: OOR < | Q26: 0 | R26: OOR < | S26: 0 | T26: OOR < | U26: 0 | V26: 178.07 | W26: 0 | X26: OOR < | Y26: 0 | Z26: OOR < | AA26: 0 | AB26: OOR < | AC26: 0 | AD26: OOR < | AE26: 0 | AF26: OOR < | AG26: 0
A27: ADRECMO | B27: box 1 | C27: ADRECMO-10_SR_J0 | D27: A026 | E27: serum | F27: OOR < | G27: 0 | H27: OOR < | I27: 0 | J27: OOR < | K27: 0 | L27: OOR < | M27: 0 | N27: OOR < | O27: 0 | P27: 31.76 | Q27: 0 | R27: 14.94 | S27: 0 | T27: 2.02 | U27: 0 | V27: 984.21 | W27: 0 | X27: OOR < | Y27: 0 | Z27: OOR < | AA27: 0 | AB27: OOR < | AC27: 0 | AD27: OOR < | AE27: 0 | AF27: OOR < | AG27: 0
A28: ADRECMO | B28: box 1 | C28: ADRECMO-10_SR_JS | D28: A027 | E28: serum | F28: OOR < | G28: 0 | H28: OOR < | I28: 0 | J28: OOR < | K28: 0 | L28: OOR < | M28: 0 | N28: *1,21 | O28: 0 | P28: 14.12 | Q28: 0 | R28: *0,66 | S28: 0 | T28: OOR < | U28: 0 | V28: 401.64 | W28: 0 | X28: OOR < | Y28: 0 | Z28: OOR < | AA28: 0 | AB28: OOR < | AC28: 0 | AD28: OOR < | AE28: 0 | AF28: OOR < | AG28: 0
